Workbook

Sheet CWP Index
A1: CWP | B1: Name | C1: Color | D1: Submittal lines (formula) | E1: Submittal gap lines (formula) | F1: ITP lines (formula) | G1: ITP gap lines (formula) | H1: First scheduled work | I1: Work span end
A2: CWP 01 | B2: General Requirements & Temporary Works | D2: =COUNTIF('Submittal Register'!A:A,A2) -> 20 | E2: =COUNTIFS('Submittal Register'!A:A,A2,'Submittal Register'!F:F,"*-00") -> 2 | F2: =COUNTIF('Inspection & Test Plan'!A:A,A2) -> 11 | G2: =COUNTIFS('Inspection & Test Plan'!A:A,A2,'Inspection & Test Plan'!F:F,"*-00") -> 0 | H2: 45000 | I2: 45581
A3: CWP 03 | B3: Concrete (Cast-in-Place & Precast) | D3: =COUNTIF('Submittal Register'!A:A,A3) -> 8 | E3: =COUNTIFS('Submittal Register'!A:A,A3,'Submittal Register'!F:F,"*-00") -> 0 | F3: =COUNTIF('Inspection & Test Plan'!A:A,A3) -> 4 | G3: =COUNTIFS('Inspection & Test Plan'!A:A,A3,'Inspection & Test Plan'!F:F,"*-00") -> 0 | H3: 45017 | I3: 45481
A4: CWP 05 | B4: Metals (Grating, Railings, Ladders, Stairs) | D4: =COUNTIF('Submittal Register'!A:A,A4) -> 7 | E4: =COUNTIFS('Submittal Register'!A:A,A4,'Submittal Register'!F:F,"*-00") -> 0 | F4: =COUNTIF('Inspection & Test Plan'!A:A,A4) -> 1 | G4: =COUNTIFS('Inspection & Test Plan'!A:A,A4,'Inspection & Test Plan'!F:F,"*-00") -> 1 | H4: 45017 | I4: 45481
A5: CWP 06 | B5: Wood, Plastics & Composites | D5: =COUNTIF('Submittal Register'!A:A,A5) -> 2 | E5: =COUNTIFS('Submittal Register'!A:A,A5,'Submittal Register'!F:F,"*-00") -> 0 | F5: =COUNTIF('Inspection & Test Plan'!A:A,A5) -> 0 | G5: =COUNTIFS('Inspection & Test Plan'!A:A,A5,'Inspection & Test Plan'!F:F,"*-00") -> 0 | H5: No scheduled work
A6: CWP 07 | B6: Thermal & Moisture Protection | D6: =COUNTIF('Submittal Register'!A:A,A6) -> 2 | E6: =COUNTIFS('Submittal Register'!A:A,A6,'Submittal Register'!F:F,"*-00") -> 0 | F6: =COUNTIF('Inspection & Test Plan'!A:A,A6) -> 1 | G6: =COUNTIFS('Inspection & Test Plan'!A:A,A6,'Inspection & Test Plan'!F:F,"*-00") -> 1 | H6: No scheduled work
A7: CWP 08 | B7: Doors, Frames & Hardware | D7: =COUNTIF('Submittal Register'!A:A,A7) -> 3 | E7: =COUNTIFS('Submittal Register'!A:A,A7,'Submittal Register'!F:F,"*-00") -> 1 | F7: =COUNTIF('Inspection & Test Plan'!A:A,A7) -> 2 | G7: =COUNTIFS('Inspection & Test Plan'!A:A,A7,'Inspection & Test Plan'!F:F,"*-00") -> 2 | H7: 45017 | I7: 45138
A8: CWP 09 | B8: Painting & Coatings | D8: =COUNTIF('Submittal Register'!A:A,A8) -> 4 | E8: =COUNTIFS('Submittal Register'!A:A,A8,'Submittal Register'!F:F,"*-00") -> 0 | F8: =COUNTIF('Inspection & Test Plan'!A:A,A8) -> 3 | G8: =COUNTIFS('Inspection & Test Plan'!A:A,A8,'Inspection & Test Plan'!F:F,"*-00") -> 2 | H8: 45078 | I8: 45224
A9: CWP 10 | B9: Specialties | D9: =COUNTIF('Submittal Register'!A:A,A9) -> 3 | E9: =COUNTIFS('Submittal Register'!A:A,A9,'Submittal Register'!F:F,"*-00") -> 0 | F9: =COUNTIF('Inspection & Test Plan'!A:A,A9) -> 3 | G9: =COUNTIFS('Inspection & Test Plan'!A:A,A9,'Inspection & Test Plan'!F:F,"*-00") -> 0 | H9: 45017 | I9: 45481
A10: CWP 13 | B10: Pre-Engineered Metal Building | D10: =COUNTIF('Submittal Register'!A:A,A10) -> 5 | E10: =COUNTIFS('Submittal Register'!A:A,A10,'Submittal Register'!F:F,"*-00") -> 0 | F10: =COUNTIF('Inspection & Test Plan'!A:A,A10) -> 1 | G10: =COUNTIFS('Inspection & Test Plan'!A:A,A10,'Inspection & Test Plan'!F:F,"*-00") -> 1 | H10: 45017 | I10: 45443
A11: CWP 22 | B11: Plumbing & Process Pumps | D11: =COUNTIF('Submittal Register'!A:A,A11) -> 6 | E11: =COUNTIFS('Submittal Register'!A:A,A11,'Submittal Register'!F:F,"*-00") -> 0 | F11: =COUNTIF('Inspection & Test Plan'!A:A,A11) -> 3 | G11: =COUNTIFS('Inspection & Test Plan'!A:A,A11,'Inspection & Test Plan'!F:F,"*-00") -> 0 | H11: 45017 | I11: 45331
A12: CWP 23 | B12: HVAC & Ventilation | D12: =COUNTIF('Submittal Register'!A:A,A12) -> 1 | E12: =COUNTIFS('Submittal Register'!A:A,A12,'Submittal Register'!F:F,"*-00") -> 0 | F12: =COUNTIF('Inspection & Test Plan'!A:A,A12) -> 0 | G12: =COUNTIFS('Inspection & Test Plan'!A:A,A12,'Inspection & Test Plan'!F:F,"*-00") -> 0 | H12: 45017 | I12: 45331
A13: CWP 26 | B13: Electrical, Instrumentation & Controls | D13: =COUNTIF('Submittal Register'!A:A,A13) -> 26 | E13: =COUNTIFS('Submittal Register'!A:A,A13,'Submittal Register'!F:F,"*-00") -> 1 | F13: =COUNTIF('Inspection & Test Plan'!A:A,A13) -> 23 | G13: =COUNTIFS('Inspection & Test Plan'!A:A,A13,'Inspection & Test Plan'!F:F,"*-00") -> 0 | H13: 45000 | I13: 45581
A14: CWP 31 | B14: Earthwork, Dewatering & Erosion Control | D14: =COUNTIF('Submittal Register'!A:A,A14) -> 11 | E14: =COUNTIFS('Submittal Register'!A:A,A14,'Submittal Register'!F:F,"*-00") -> 0 | F14: =COUNTIF('Inspection & Test Plan'!A:A,A14) -> 9 | G14: =COUNTIFS('Inspection & Test Plan'!A:A,A14,'Inspection & Test Plan'!F:F,"*-00") -> 0 | H14: 45000 | I14: 45581
A15: CWP 32 | B15: Paving, Fencing, Walls & Landscaping | D15: =COUNTIF('Submittal Register'!A:A,A15) -> 6 | E15: =COUNTIFS('Submittal Register'!A:A,A15,'Submittal Register'!F:F,"*-00") -> 0 | F15: =COUNTIF('Inspection & Test Plan'!A:A,A15) -> 2 | G15: =COUNTIFS('Inspection & Test Plan'!A:A,A15,'Inspection & Test Plan'!F:F,"*-00") -> 0 | H15: 45000 | I15: 45581
A16: CWP 33 | B16: Yard Piping & Utilities | D16: =COUNTIF('Submittal Register'!A:A,A16) -> 14 | E16: =COUNTIFS('Submittal Register'!A:A,A16,'Submittal Register'!F:F,"*-00") -> 1 | F16: =COUNTIF('Inspection & Test Plan'!A:A,A16) -> 21 | G16: =COUNTIFS('Inspection & Test Plan'!A:A,A16,'Inspection & Test Plan'!F:F,"*-00") -> 1 | H16: 45017 | I16: 45481
A17: CWP 40 | B17: Process Interconnections | D17: =COUNTIF('Submittal Register'!A:A,A17) -> 1 | E17: =COUNTIFS('Submittal Register'!A:A,A17,'Submittal Register'!F:F,"*-00") -> 0 | F17: =COUNTIF('Inspection & Test Plan'!A:A,A17) -> 0 | G17: =COUNTIFS('Inspection & Test Plan'!A:A,A17,'Inspection & Test Plan'!F:F,"*-00") -> 0 | H17: 45017 | I17: 45231
A18: CWP 41 | B18: Material Handling (Screw Conveyors) | D18: =COUNTIF('Submittal Register'!A:A,A18) -> 1 | E18: =COUNTIFS('Submittal Register'!A:A,A18,'Submittal Register'!F:F,"*-00") -> 0 | F18: =COUNTIF('Inspection & Test Plan'!A:A,A18) -> 1 | G18: =COUNTIFS('Inspection & Test Plan'!A:A,A18,'Inspection & Test Plan'!F:F,"*-00") -> 1 | H18: 45231 | I18: 45331
... A21: CWP 46 | B21: Treatment Equipment | D21: =COUNTIF('Submittal Register'!A:A,A21) -> 19 | E21: =COUNTIFS('Submittal Register'!A:A,A21,'Submittal Register'!F:F,"*-00") -> 1 | F21: =COUNTIF('Inspection & Test Plan'!A:A,A21) -> 13 | G21: =COUNTIFS('Inspection & Test Plan'!A:A,A21,'Inspection & Test Plan'!F:F,"*-00") -> 1 | H21: 45017 | I21: 45481
A22: Total | D22: =SUM(D2:D21) -> 145 | E22: =SUM(E2:E21) -> 6 | F22: =SUM(F2:F21) -> 103 | G22: =SUM(G2:G21) -> 11

Sheet Submittal Register
A1: CWP | B1: CWP Name | C1: CWP Basis | D1: Schedule date (Inferred) | E1: Schedule activity | F1: Req ID | G1: Req Type | H1: Item | I1: Subtype | J1: Timing/Frequency | K1: Acceptance Criteria | L1: Responsible Party | M1: Spec Sections | N1: Drawing Sheets | O1: Tag(s) | P1: Bid Item | Q1: Addenda | R1: Lane | S1: Verified/Verified-Visual/Inferred/Unresolved | T1: Source Citation | U1: Notes
A2: CWP 01 | B2: General Requirements & Temporary Works | C2: Sheet prefix G (no linked rows) — Inferred | D2: Approve by 2023-03-15 (CWP 01 first work, Inferred) | E2: 01-P01 | F2: SUB G0.4-01 | G2: Submittal | H2: Utility lines come from surface-visible structures and locate marks, and Wilson does not guarantee their accuracy | I2: Warranty / guarantee | J2: Not stated | K2: n/a — submittal | L2: Contractor (submits per 01 33 00 — Inferred) | N2: G0.4 | O2: None linked | P2: Not stated | Q2: — | R2: Civil & Site | S2: Verified | T2: Project_Wiki.md note G0.4 (Civil & Site): (Notes 3.A–3.C; plans_1 p.4, G0.4 — Verified) | U2: Requirement sentence taken verbatim from the note; Subtype, Timing, Acceptance and Responsible Party parsed from it by keyword (Merge, Inferred — check against the cited ¶). Linked Ledger rows: 0 (flag Y and sheet cited; linkage Inferred).
A3: CWP 01 | B3: General Requirements & Temporary Works | C3: Spec 00 51 00 (Division 00/01 → CWP 01) | D3: Approve by 2023-03-15 (CWP 01 first work, Inferred) | E3: 01-P01 | F3: SUB 00 51 00-01 | G3: Submittal | H3: It requires the contractor to execute the Contract and furnish bonds and certificates of insurance within ten (10) calendar days of the notice, but the forfeiture sentence uses ten (10) working days | I3: Certificates / reports | J3: within ten (10 | K3: n/a — submittal | L3: Contractor (submits per 01 33 00 — Inferred) | M3: 00 51 00 | O3: None linked | P3: Not stated | Q3: — | R3: Contract & General | S3: Unresolved | T3: Project_Wiki.md note 00 51 00 (Contract & General): (p.38; Issues 1.3, Unresolved) | U3: Requirement sentence taken verbatim from the note; Subtype, Timing, Acceptance and Responsible Party parsed from it by keyword (Merge, Inferred — check against the cited ¶). Linked Ledger rows: 0 (flag Y and section cited; linkage Inferred).
A4: CWP 01 | B4: General Requirements & Temporary Works | C4: Spec 00 53 00 (Division 00/01 → CWP 01) | D4: Approve by 2023-03-15 (CWP 01 first work, Inferred) | E4: 01-P01 | F4: SUB 00 53 00-01 | G4: Submittal | H4: Required with the bid: Certification of Nonsegregated Facilities (Attachment 3), EPA DBE forms 6100-4 and 6100-3 (one per DBE sub; forms on the Ecology website), and the complete Bidders List (p.41; Verified); pp.45–46 then allow the DBE forms and the Bidders List "as part of the bid, or within one hour" after bid time (Verified) — timing conflicts inside this section and with 00 43 93 and 01 33 00 | I4: Certificates / reports | J4: within one hour" after bid time (Verified; with the bid | K4: n/a — submittal | L4: Contractor (submits per 01 33 00 — Inferred) | M4: 00 53 00 | O4: None linked | P4: Not stated | Q4: — | R4: Contract & General | S4: Verified | T4: Project_Wiki.md note 00 53 00 (Contract & General): (Issues 1.6) | U4: Requirement sentence taken verbatim from the note; Subtype, Timing, Acceptance and Responsible Party parsed from it by keyword (Merge, Inferred — check against the cited ¶). Linked Ledger rows: 0 (flag Y and section cited; linkage Inferred).
A5: CWP 01 | B5: General Requirements & Temporary Works | C5: Spec 00 53 00 (Division 00/01 → CWP 01) | D5: Approve by 2023-03-15 (CWP 01 first work, Inferred) | E5: 01-P01 | F5: SUB 00 53 00-02 | G5: Submittal | H5: American Iron and Steel applies to treatment works: iron and steel products (pipe and fittings, castings, hydrants, tanks, flanges, restraints, valves, structural steel, reinforced precast, construction materials) must be US-produced unless waived, with certification on request and damages for non-compliance | I5: Certificates / reports | J5: Not stated | K5: n/a — submittal | L5: Contractor (submits per 01 33 00 — Inferred) | M5: 00 53 00 | O5: None linked | P5: Not stated | Q5: — | R5: Contract & General | S5: Verified | T5: Project_Wiki.md note 00 53 00 (Contract & General): (pp.42–43; Verified) | U5: Requirement sentence taken verbatim from the note; Subtype, Timing, Acceptance and Responsible Party parsed from it by keyword (Merge, Inferred — check against the cited ¶). Linked Ledger rows: 0 (flag Y and section cited; linkage Inferred).
A6: CWP 01 | B6: General Requirements & Temporary Works | C6: Spec 00 54 00 (Division 00/01 → CWP 01) | D6: Approve by 2023-03-15 (CWP 01 first work, Inferred) | E6: 01-P01 | F6: SUB 00 54 00-01 | G6: Submittal | H6: HUD-4010 federal labor standards require weekly certified payrolls, and state prevailing wage (RCW 39.12) requires L&I-approved Statements of Intent before any payment and Affidavits of Wages Paid before retainage release under RCW 60.28.010 | I6: Certificates / reports | J6: before any payment and Affidavits of Wages Paid before retain; weekly | K6: n/a — submittal | L6: Contractor (submits per 01 33 00 — Inferred) | M6: 00 54 00 | O6: None linked | P6: Not stated | Q6: — | R6: Contract & General | S6: Verified | T6: Project_Wiki.md note 00 54 00 (Contract & General): (pp.68–74; Verified) | U6: Requirement sentence taken verbatim from the note; Subtype, Timing, Acceptance and Responsible Party parsed from it by keyword (Merge, Inferred — check against the cited ¶). Linked Ledger rows: 0 (flag Y and section cited; linkage Inferred).
A7: CWP 01 | B7: General Requirements & Temporary Works | C7: Spec 00 73 00 (Division 00/01 → CWP 01) | D7: Approve by 2023-03-15 (CWP 01 first work, Inferred) | E7: 01-P01 | F7: SUB 00 73 00-01 | G7: Submittal | H7: Red-line record drawings before 90% payment, temporary barriers at all hazards, insurance ($1M/$2M bodily injury, $1M property damage, builders risk equal to the bid, Owner and Engineer additional insured), one-year guarantee (start date conflicts — Issues 1.11), and funding clauses follow (SC 20–35, pp.92–97; Verified); pp.98–121 repeat the 00 53 00 Ecology insert word for word | I7: Warranty / guarantee | J7: Not stated | K7: n/a — submittal | L7: Contractor (submits per 01 33 00 — Inferred); also named: Owner; Engineer | M7: 00 73 00 | N7: C6.4; C6.5; A1.1; A1.2; A1.3; S1.1; S2.3 | O7: PROPOSED-BLOWER-BUILDING; PROPOSED-Blower-Building; PROPOSED-UV-Disinfection-System; PROPOSED-Permanent-Standby-Generator; PROPOSED-PLC-Control-Panel; PROPOSED-Dewatering-System | P7: 1; 6; Equipment Alternate C; Equipment Alternate D; Equipment Alternate E | Q7: — | R7: Contract & General | S7: Inferred | T7: Project_Wiki.md note 00 73 00 (Contract & General): (Issues 1.13) | U7: Requirement sentence taken verbatim from the note; Subtype, Timing, Acceptance and Responsible Party parsed from it by keyword (Merge, Inferred — check against the cited ¶). Linked Ledger rows: 5 (flag Y and section cited; linkage Inferred).
A8: CWP 01 | B8: General Requirements & Temporary Works | C8: Spec 01 33 00 (Division 00/01 → CWP 01) | D8: Approve by 2023-03-15 (CWP 01 first work, Inferred) | E8: 01-P01 | F8: SUB 01 33 00-01 | G8: Submittal | H8: Gives general submittal procedures and a non-exhaustive checklist; item-specific requirements sit in the individual sections | I8: Plan / procedure | J8: Not stated | K8: n/a — submittal | L8: Contractor (submits per 01 33 00 — Inferred) | M8: 01 33 00 | O8: PROPOSED-8in-Effluent-Flow-Meter; PROPOSED-UV-Disinfection-System; PROPOSED-Sludge-Pumps; PROPOSED-2W-Air-Gap-Water-System; PROPOSED-Submersible-Pump-Equipment; PROPOSED-Influent-Sampler; PROPOSED-Train-3-Biological-Treatment-Equipment; PROPOSED-Automatic-Transfer-Switch; PROPOSED-Permanent-Standby-Generator; PROPOSED-480V-Electrical-Service; PROPOSED-Motor-Control-Center; PROPOSED-PLC-Control-Panel; PROPOSED-Dewatering-System; PROPOSED-Bypass-Pumping-System; PROPOSED-Blowers; PROPOSED-Train-3-Dissolved-Oxygen-Sensors; PROPOSED-Train-3-pH-Sensors; PROPOSED-Magnetic-Flow-Meters | P8: 1; 6; 18 — Unresolved (see 04); 19; Equipment Alternate A; Equipment Alternate B; Equipment Alternate C; Equipment Alternate D; Equipment Alternate E | Q8: — | R8: Contract & General | S8: Inferred | T8: Project_Wiki.md note 01 33 00 (Contract & General): (¶1.01, ¶1.03, p.129; Verified) | U8: Requirement sentence taken verbatim from the note; Subtype, Timing, Acceptance and Responsible Party parsed from it by keyword (Merge, Inferred — check against the cited ¶). Linked Ledger rows: 18 (flag Y and section cited; linkage Inferred).
A9: CWP 01 | B9: General Requirements & Temporary Works | C9: Spec 01 33 00 (Division 00/01 → CWP 01) | D9: Approve by 2023-03-15 (CWP 01 first work, Inferred) | E9: 01-P01 | F9: SUB 01 33 00-02 | G9: Submittal | H9: The checklist's bid-phase entries cite sections and attachments that do not exist in the project manual — 00 43 36, 00 22 13, 00 45 14, and DBE forms as "Attachments 6 and 7" of 00 73 00 — and move Contractor Qualifications to 24 hours after opening | I9: O&M manual; Qualifications | J9: Not stated | K9: n/a — submittal | L9: Contractor (submits per 01 33 00 — Inferred) | M9: 01 33 00 | O9: PROPOSED-8in-Effluent-Flow-Meter; PROPOSED-UV-Disinfection-System; PROPOSED-Sludge-Pumps; PROPOSED-2W-Air-Gap-Water-System; PROPOSED-Submersible-Pump-Equipment; PROPOSED-Influent-Sampler; PROPOSED-Train-3-Biological-Treatment-Equipment; PROPOSED-Automatic-Transfer-Switch; PROPOSED-Permanent-Standby-Generator; PROPOSED-480V-Electrical-Service; PROPOSED-Motor-Control-Center; PROPOSED-PLC-Control-Panel; PROPOSED-Dewatering-System; PROPOSED-Bypass-Pumping-System; PROPOSED-Blowers; PROPOSED-Train-3-Dissolved-Oxygen-Sensors; PROPOSED-Train-3-pH-Sensors; PROPOSED-Magnetic-Flow-Meters | P9: 1; 6; 18 — Unresolved (see 04); 19; Equipment Alternate A; Equipment Alternate B; Equipment Alternate C; Equipment Alternate D; Equipment Alternate E | Q9: — | R9: Contract & General | S9: Inferred | T9: Project_Wiki.md note 01 33 00 (Contract & General): (¶1.03.A–C, p.129; Issues 1.14, 2.2, 2.5) | U9: Requirement sentence taken verbatim from the note; Subtype, Timing, Acceptance and Responsible Party parsed from it by keyword (Merge, Inferred — check against the cited ¶). Linked Ledger rows: 18 (flag Y and section cited; linkage Inferred).
A10: CWP 01 | B10: General Requirements & Temporary Works | C10: Spec 01 33 00 (Division 00/01 → CWP 01) | D10: Approve by 2023-03-15 (CWP 01 first work, Inferred) | E10: 01-P01 | F10: SUB 01 33 00-03 | G10: Submittal | H10: Before the Agreement: bonds, insurance certificates, prevailing wage filings; 10 days after execution: construction schedule, substitution requests, Schedule of Values; monthly: pay application and updated schedule; certified payroll; 14 days before any WWTP shutdown: a bypass pumping and emergency response plan; closeout: affidavits, record drawings | I10: Certificates / reports; Plan / procedure | J10: 10 days after execution: construction schedule; 14 days before any WWTP shutdown: a bypass pumping and; Before the Agreement: bonds | K10: n/a — submittal | L10: Contractor (submits per 01 33 00 — Inferred) | M10: 01 33 00 | O10: PROPOSED-8in-Effluent-Flow-Meter; PROPOSED-UV-Disinfection-System; PROPOSED-Sludge-Pumps; PROPOSED-2W-Air-Gap-Water-System; PROPOSED-Submersible-Pump-Equipment; PROPOSED-Influent-Sampler; PROPOSED-Train-3-Biological-Treatment-Equipment; PROPOSED-Automatic-Transfer-Switch; PROPOSED-Permanent-Standby-Generator; PROPOSED-480V-Electrical-Service; PROPOSED-Motor-Control-Center; PROPOSED-PLC-Control-Panel; PROPOSED-Dewatering-System; PROPOSED-Bypass-Pumping-System; PROPOSED-Blowers; PROPOSED-Train-3-Dissolved-Oxygen-Sensors; PROPOSED-Train-3-pH-Sensors; PROPOSED-Magnetic-Flow-Meters | P10: 1; 6; 18 — Unresolved (see 04); 19; Equipment Alternate A; Equipment Alternate B; Equipment Alternate C; Equipment Alternate D; Equipment Alternate E | Q10: — | R10: Contract & General | S10: Inferred | T10: Project_Wiki.md note 01 33 00 (Contract & General): (¶1.03.D–J, pp.129–130; Verified) | U10: Requirement sentence taken verbatim from the note; Subtype, Timing, Acceptance and Responsible Party parsed from it by keyword (Merge, Inferred — check against the cited ¶). Linked Ledger rows: 18 (flag Y and section cited; linkage Inferred).
A11: CWP 01 | B11: General Requirements & Temporary Works | C11: Spec 01 33 00 (Division 00/01 → CWP 01) | D11: Approve by 2023-03-15 (CWP 01 first work, Inferred) | E11: 01-P01 | F11: SUB 01 33 00-04 | G11: Submittal | H11: Submittals are PDF with a transmittal, stamped by the Contractor, with an approved-submittal file kept on site; samples in pairs, product certificates in triplicate, test reports 3 copies | I11: Calculations / sealed design; Certificates / reports; Samples | J11: Not stated | K11: n/a — submittal | L11: Contractor (submits per 01 33 00 — Inferred) | M11: 01 33 00 | O11: PROPOSED-8in-Effluent-Flow-Meter; PROPOSED-UV-Disinfection-System; PROPOSED-Sludge-Pumps; PROPOSED-2W-Air-Gap-Water-System; PROPOSED-Submersible-Pump-Equipment; PROPOSED-Influent-Sampler; PROPOSED-Train-3-Biological-Treatment-Equipment; PROPOSED-Automatic-Transfer-Switch; PROPOSED-Permanent-Standby-Generator; PROPOSED-480V-Electrical-Service; PROPOSED-Motor-Control-Center; PROPOSED-PLC-Control-Panel; PROPOSED-Dewatering-System; PROPOSED-Bypass-Pumping-System; PROPOSED-Blowers; PROPOSED-Train-3-Dissolved-Oxygen-Sensors; PROPOSED-Train-3-pH-Sensors; PROPOSED-Magnetic-Flow-Meters | P11: 1; 6; 18 — Unresolved (see 04); 19; Equipment Alternate A; Equipment Alternate B; Equipment Alternate C; Equipment Alternate D; Equipment Alternate E | Q11: — | R11: Contract & General | S11: Inferred | T11: Project_Wiki.md note 01 33 00 (Contract & General): (¶1.04–1.05, pp.130–131; Verified) | U11: Requirement sentence taken verbatim from the note; Subtype, Timing, Acceptance and Responsible Party parsed from it by keyword (Merge, Inferred — check against the cited ¶). Linked Ledger rows: 18 (flag Y and section cited; linkage Inferred).
A12: CWP 01 | B12: General Requirements & Temporary Works | C12: Spec 01 33 00 (Division 00/01 → CWP 01) | D12: Approve by 2023-03-15 (CWP 01 first work, Inferred) | E12: 01-P01 | F12: SUB 01 33 00-05 | G12: Submittal | H12: O&M manuals (4 hard, 2 PDF sets) go in draft with shop drawings, final draft before the 75% pay application, and complete before payment above 90% | I12: Shop drawings; O&M manual | J12: before the 75% pay application; before payment above 90% (¶1 | K12: n/a — submittal | L12: Contractor (submits per 01 33 00 — Inferred) | M12: 01 33 00 | O12: PROPOSED-8in-Effluent-Flow-Meter; PROPOSED-UV-Disinfection-System; PROPOSED-Sludge-Pumps; PROPOSED-2W-Air-Gap-Water-System; PROPOSED-Submersible-Pump-Equipment; PROPOSED-Influent-Sampler; PROPOSED-Train-3-Biological-Treatment-Equipment; PROPOSED-Automatic-Transfer-Switch; PROPOSED-Permanent-Standby-Generator; PROPOSED-480V-Electrical-Service; PROPOSED-Motor-Control-Center; PROPOSED-PLC-Control-Panel; PROPOSED-Dewatering-System; PROPOSED-Bypass-Pumping-System; PROPOSED-Blowers; PROPOSED-Train-3-Dissolved-Oxygen-Sensors; PROPOSED-Train-3-pH-Sensors; PROPOSED-Magnetic-Flow-Meters | P12: 1; 6; 18 — Unresolved (see 04); 19; Equipment Alternate A; Equipment Alternate B; Equipment Alternate C; Equipment Alternate D; Equipment Alternate E | Q12: — | R12: Contract & General | S12: Inferred | T12: Project_Wiki.md note 01 33 00 (Contract & General): (¶1.05.G, pp.131–132; Verified) | U12: Requirement sentence taken verbatim from the note; Subtype, Timing, Acceptance and Responsible Party parsed from it by keyword (Merge, Inferred — check against the cited ¶). Linked Ledger rows: 18 (flag Y and section cited; linkage Inferred).
A13: CWP 01 | B13: General Requirements & Temporary Works | C13: Spec 01 70 00 (Division 00/01 → CWP 01) | D13: Approve by 2023-03-15 (CWP 01 first work, Inferred) | E13: 01-P01 | F13: SUB 01 70 00-01 | G13: Submittal | H13: Before requesting Substantial Completion the Contractor delivers tools, spare parts and extra stock, changes over locks and hands over keys, completes start-up testing and operator instruction, removes temporary facilities, turns over record information, finishes cleanup, and provides O&M manuals for all equipment, controls, telemetry and SCADA plus 2015 WSEC compliance documentation per C103.6.3 | I13: O&M manual | J13: Not stated | K13: n/a — submittal | L13: Contractor (submits per 01 33 00 — Inferred) | M13: 01 70 00 | N13: C6.4; C6.5; A1.1; A1.2; A1.3; S1.1; S2.3 | O13: PROPOSED-BLOWER-BUILDING; PROPOSED-Blower-Building; PROPOSED-8in-Effluent-Flow-Meter; PROPOSED-UV-Disinfection-System; PROPOSED-Sludge-Pumps; PROPOSED-2W-Air-Gap-Water-System; PROPOSED-Submersible-Pump-Equipment; PROPOSED-Influent-Sampler; PROPOSED-Train-3-Biological-Treatment-Equipment; PROPOSED-Automatic-Transfer-Switch; PROPOSED-Permanent-Standby-Generator; PROPOSED-480V-Electrical-Service; PROPOSED-Motor-Control-Center; PROPOSED-PLC-Control-Panel; PROPOSED-Dewatering-System; PROPOSED-Blowers; PROPOSED-Train-3-Dissolved-Oxygen-Sensors; PROPOSED-Train-3-pH-Sensors; PROPOSED-Magnetic-Flow-Meters | P13: 1; 6; 18 — Unresolved (see 04); 19; Equipment Alternate A; Equipment Alternate B; Equipment Alternate C; Equipment Alternate D; Equipment Alternate E | Q13: — | R13: Contract & General | S13: Inferred | T13: Project_Wiki.md note 01 70 00 (Contract & General): (¶1.03.A, pp.152–153; Verified; temporary facility removal conflicts with 00 73 00 SC 19 — Issues 1.19; energy code edition — Issues 1.20) | U13: Requirement sentence taken verbatim from the note; Subtype, Timing, Acceptance and Responsible Party parsed from it by keyword (Merge, Inferred — check against the cited ¶). Linked Ledger rows: 18 (flag Y and section cited; linkage Inferred).
A14: CWP 01 | B14: General Requirements & Temporary Works | C14: Spec 01 70 00 (Division 00/01 → CWP 01) | D14: Approve by 2023-03-15 (CWP 01 first work, Inferred) | E14: 01-P01 | F14: SUB 01 70 00-02 | G14: Submittal | H14: The request carries a completion notice, incomplete-items list, pay request, change accounting, warranties and bonds, releases and occupancy/operating certificates, and record documents; "substantially complete" is defined by the WSDOT General Specifications and "Sections 00 72 00 and 00 73 00a" (¶1.03.B, p.153; WSDOT part Unresolved: external reference, not staged; section numbers — Issues 2.5), and warranties start on the Date of Substantial Completion | I14: Certificates / reports; Warranty / guarantee | J14: Not stated | K14: n/a — submittal | L14: Contractor (submits per 01 33 00 — Inferred) | M14: 01 70 00 | N14: C6.4; C6.5; A1.1; A1.2; A1.3; S1.1; S2.3 | O14: PROPOSED-BLOWER-BUILDING; PROPOSED-Blower-Building; PROPOSED-8in-Effluent-Flow-Meter; PROPOSED-UV-Disinfection-System; PROPOSED-Sludge-Pumps; PROPOSED-2W-Air-Gap-Water-System; PROPOSED-Submersible-Pump-Equipment; PROPOSED-Influent-Sampler; PROPOSED-Train-3-Biological-Treatment-Equipment; PROPOSED-Automatic-Transfer-Switch; PROPOSED-Permanent-Standby-Generator; PROPOSED-480V-Electrical-Service; PROPOSED-Motor-Control-Center; PROPOSED-PLC-Control-Panel; PROPOSED-Dewatering-System; PROPOSED-Blowers; PROPOSED-Train-3-Dissolved-Oxygen-Sensors; PROPOSED-Train-3-pH-Sensors; PROPOSED-Magnetic-Flow-Meters | P14: 1; 6; 18 — Unresolved (see 04); 19; Equipment Alternate A; Equipment Alternate B; Equipment Alternate C; Equipment Alternate D; Equipment Alternate E | Q14: — | R14: Contract & General | S14: Inferred | T14: Project_Wiki.md note 01 70 00 (Contract & General): (¶1.03.D.1, p.153; Verified; bears on Issues 1.11) | U14: Requirement sentence taken verbatim from the note; Subtype, Timing, Acceptance and Responsible Party parsed from it by keyword (Merge, Inferred — check against the cited ¶). Linked Ledger rows: 18 (flag Y and section cited; linkage Inferred).
A15: CWP 01 | B15: General Requirements & Temporary Works | C15: Spec 01 70 00 (Division 00/01 → CWP 01) | D15: Approve by 2023-03-15 (CWP 01 first work, Inferred) | E15: 01-P01 | F15: SUB 01 70 00-03 | G15: Submittal | H15: Retainage is released only against an affidavit of paid payrolls and bills, lien releases, the DOR tax form, the L&I affidavit of wages paid and the ESD release | I15: Certificates / reports | J15: Not stated | K15: n/a — submittal | L15: Contractor (submits per 01 33 00 — Inferred) | M15: 01 70 00 | N15: C6.4; C6.5; A1.1; A1.2; A1.3; S1.1; S2.3 | O15: PROPOSED-BLOWER-BUILDING; PROPOSED-Blower-Building; PROPOSED-8in-Effluent-Flow-Meter; PROPOSED-UV-Disinfection-System; PROPOSED-Sludge-Pumps; PROPOSED-2W-Air-Gap-Water-System; PROPOSED-Submersible-Pump-Equipment; PROPOSED-Influent-Sampler; PROPOSED-Train-3-Biological-Treatment-Equipment; PROPOSED-Automatic-Transfer-Switch; PROPOSED-Permanent-Standby-Generator; PROPOSED-480V-Electrical-Service; PROPOSED-Motor-Control-Center; PROPOSED-PLC-Control-Panel; PROPOSED-Dewatering-System; PROPOSED-Blowers; PROPOSED-Train-3-Dissolved-Oxygen-Sensors; PROPOSED-Train-3-pH-Sensors; PROPOSED-Magnetic-Flow-Meters | P15: 1; 6; 18 — Unresolved (see 04); 19; Equipment Alternate A; Equipment Alternate B; Equipment Alternate C; Equipment Alternate D; Equipment Alternate E | Q15: — | R15: Contract & General | S15: Inferred | T15: Project_Wiki.md note 01 70 00 (Contract & General): (¶1.05.B, p.154; Verified) | U15: Requirement sentence taken verbatim from the note; Subtype, Timing, Acceptance and Responsible Party parsed from it by keyword (Merge, Inferred — check against the cited ¶). Linked Ledger rows: 18 (flag Y and section cited; linkage Inferred).
A16: CWP 01 | B16: General Requirements & Temporary Works | C16: Spec 01 70 00 (Division 00/01 → CWP 01) | D16: Approve by 2023-03-15 (CWP 01 first work, Inferred) | E16: 01-P01 | F16: SUB 01 70 00-04 | G16: Submittal | H16: All mechanical and electrical equipment is tested before any facility goes into operation: procedures due 14 days before start-up covering every control device, equipment item and control circuit, joint sign-off forms, testing witnessed by the Engineer, and manufacturers' representatives who train Owner staff and certify each installation by letter | I16: Certificates / reports; Plan / procedure | J16: 14 days before start-up covering every control device; before any facility goes into operation: procedures due 14 da; before start-up covering every control device | K16: n/a — submittal | L16: Contractor (submits per 01 33 00 — Inferred); also named: Owner; Engineer; Manufacturer / supplier | M16: 01 70 00 | N16: C6.4; C6.5; A1.1; A1.2; A1.3; S1.1; S2.3 | O16: PROPOSED-BLOWER-BUILDING; PROPOSED-Blower-Building; PROPOSED-8in-Effluent-Flow-Meter; PROPOSED-UV-Disinfection-System; PROPOSED-Sludge-Pumps; PROPOSED-2W-Air-Gap-Water-System; PROPOSED-Submersible-Pump-Equipment; PROPOSED-Influent-Sampler; PROPOSED-Train-3-Biological-Treatment-Equipment; PROPOSED-Automatic-Transfer-Switch; PROPOSED-Permanent-Standby-Generator; PROPOSED-480V-Electrical-Service; PROPOSED-Motor-Control-Center; PROPOSED-PLC-Control-Panel; PROPOSED-Dewatering-System; PROPOSED-Blowers; PROPOSED-Train-3-Dissolved-Oxygen-Sensors; PROPOSED-Train-3-pH-Sensors; PROPOSED-Magnetic-Flow-Meters | P16: 1; 6; 18 — Unresolved (see 04); 19; Equipment Alternate A; Equipment Alternate B; Equipment Alternate C; Equipment Alternate D; Equipment Alternate E | Q16: — | R16: Contract & General | S16: Inferred | T16: Project_Wiki.md note 01 70 00 (Contract & General): (¶1.06, p.155; Verified) | U16: Requirement sentence taken verbatim from the note; Subtype, Timing, Acceptance and Responsible Party parsed from it by keyword (Merge, Inferred — check against the cited ¶). Linked Ledger rows: 18 (flag Y and section cited; linkage Inferred).
A17: CWP 01 | B17: General Requirements & Temporary Works | C17: Spec 01 91 00 (Division 00/01 → CWP 01) | D17: Approve by 2023-03-15 (CWP 01 first work, Inferred) | E17: 01-P01 | F17: SUB 01 91 00-01 | G17: Submittal | H17: Sets minimum supplier start-up supervision and operator training as a non-exhaustive checklist; every entry covers installation inspection, motor amperage checks, access, controls operation, an O&M manual review and controls training | I17: O&M manual | J17: Not stated | K17: n/a — submittal | L17: Contractor (submits per 01 33 00 — Inferred); also named: Manufacturer / supplier | M17: 01 91 00 | O17: PROPOSED-UV-Disinfection-System; PROPOSED-Sludge-Pumps; PROPOSED-2W-Air-Gap-Water-System; PROPOSED-Submersible-Pump-Equipment; PROPOSED-Train-3-Biological-Treatment-Equipment; PROPOSED-Dewatering-System; PROPOSED-Blowers; PROPOSED-Train-3-Dissolved-Oxygen-Sensors; PROPOSED-Train-3-pH-Sensors; PROPOSED-Magnetic-Flow-Meters | P17: 1; 18 — Unresolved (see 04); 19; Equipment Alternate A; Equipment Alternate B; Equipment Alternate C; Equipment Alternate D | Q17: — | R17: Contract & General | S17: Inferred | T17: Project_Wiki.md note 01 91 00 (Contract & General): (¶1.01.B, pp.157–160; Verified) | U17: Requirement sentence taken verbatim from the note; Subtype, Timing, Acceptance and Responsible Party parsed from it by keyword (Merge, Inferred — check against the cited ¶). Linked Ledger rows: 10 (flag Y and section cited; linkage Inferred).
A18: CWP 01 | B18: General Requirements & Temporary Works | C18: Spec 01 91 00 (Division 00/01 → CWP 01) | D18: Approve by 2023-03-15 (CWP 01 first work, Inferred) | E18: 01-P01 | F18: SUB 01 91 00-02 | G18: Submittal | H18: Dewatering equipment suppliers each give "a minimum of one (2) days" (¶1.07, p.159; Unresolved — Issues 1.21); the 2W water system supplier 1 day, verifying constant 60–90 psi from 0 to 50 gpm, the automatic valve at the air gap and the floats; the magnetic flow meter supplier 2 days, checking that submerged units are sealed and rated | I18: Calculations / sealed design | J18: Not stated | K18: n/a — submittal | L18: Contractor (submits per 01 33 00 — Inferred); also named: Manufacturer / supplier | M18: 01 91 00 | O18: PROPOSED-UV-Disinfection-System; PROPOSED-Sludge-Pumps; PROPOSED-2W-Air-Gap-Water-System; PROPOSED-Submersible-Pump-Equipment; PROPOSED-Train-3-Biological-Treatment-Equipment; PROPOSED-Dewatering-System; PROPOSED-Blowers; PROPOSED-Train-3-Dissolved-Oxygen-Sensors; PROPOSED-Train-3-pH-Sensors; PROPOSED-Magnetic-Flow-Meters | P18: 1; 18 — Unresolved (see 04); 19; Equipment Alternate A; Equipment Alternate B; Equipment Alternate C; Equipment Alternate D | Q18: — | R18: Contract & General | S18: Inferred | T18: Project_Wiki.md note 01 91 00 (Contract & General): (¶1.10–1.11, pp.159–160; Verified) | U18: Requirement sentence taken verbatim from the note; Subtype, Timing, Acceptance and Responsible Party parsed from it by keyword (Merge, Inferred — check against the cited ¶). Linked Ledger rows: 10 (flag Y and section cited; linkage Inferred).
A19: CWP 01 | B19: General Requirements & Temporary Works | C19: Spec 15 08 13; Temporary Construction Sign → Division 01 (MasterFormat 2004: 01 58 13) | D19: Approve by 2023-03-15 (CWP 01 first work, Inferred) | E19: 01-P01 | F19: SUB 15 08 13-01 | G19: Submittal | H19: Submittal: proof of graphics before printing | I19: General submittal | J19: Not stated | K19: n/a — submittal | L19: Contractor (submits per 01 33 00 — Inferred) | M19: 15 08 13 | O19: PROPOSED-Temporary construction sign | P19: 1 | Q19: — | R19: Civil & Site | S19: Inferred | T19: Project_Wiki.md note 15 08 13 (Civil & Site): (¶1.01; p.252 — Verified) | U19: Requirement sentence taken verbatim from the note; Subtype, Timing, Acceptance and Responsible Party parsed from it by keyword (Merge, Inferred — check against the cited ¶). Linked Ledger rows: 1 (flag Y and section cited; linkage Inferred).
A20: CWP 01 | B20: General Requirements & Temporary Works | C20: Spec 01 45 00 (Division 00/01 → CWP 01) | D20: Approve by 2023-03-15 (CWP 01 first work, Inferred) | E20: 01-P01 | F20: SUB 01 45 00-00 | G20: Submittal | H20: Requirement flagged on 5 Ledger row(s) citing 01 45 00; the Wiki note does not summarize it | I20: Not stated | J20: Not stated | K20: Not stated | L20: Not stated | M20: 01 45 00 | N20: C4.2; C6.4; C6.5; A1.1; A1.2; A1.3; S1.1; S2.3 | O20: PROPOSED-2W-PUMP-STATION-WET-WELL; PROPOSED-2W-Pump-Station-Wet-Well; PROPOSED-BLOWER-BUILDING; PROPOSED-Blower-Building; PROPOSED-Sludge-Pumps; PROPOSED-Submersible-Pump-Equipment; PROPOSED-Train-3-Biological-Treatment-Equipment | P20: 1; 18 — Unresolved (see 04); 19; Equipment Alternate A; Equipment Alternate B | Q20: — | R20: Process & Mechanical; Contract & General; Process & Mechanical; Structural & Building; Contract & General; Contract & General | S20: Unresolved | T20: Ledger evidence: flag only — no paragraph cited in the rows | U20: Gap row: Ledger says a requirement exists but the Wiki note carries no requirement sentence. Needed: the section's requirement paragraphs captured as Requirements rows at crawl time.
A21: CWP 01 | B21: General Requirements & Temporary Works | C21: Spec 01 50 00 (Division 00/01 → CWP 01) | D21: Approve by 2023-03-15 (CWP 01 first work, Inferred) | E21: 01-P01 | F21: SUB 01 50 00-00 | G21: Submittal | H21: Requirement flagged on 2 Ledger row(s) citing 01 50 00; the Wiki note does not summarize it | I21: Not stated | J21: Not stated | K21: Not stated | L21: Not stated | M21: 01 50 00 | N21: C4.2 | O21: PROPOSED-2W-PUMP-STATION-WET-WELL; PROPOSED-2W-Pump-Station-Wet-Well; PROPOSED-Bypass-Pumping-System | P21: 1 | Q21: — | R21: Process & Mechanical; Contract & General; Contract & General | S21: Unresolved | T21: Ledger evidence: flag only — no paragraph cited in the rows | U21: Gap row: Ledger says a requirement exists but the Wiki note carries no requirement sentence. Needed: the section's requirement paragraphs captured as Requirements rows at crawl time.
A22: CWP 03 | B22: Concrete (Cast-in-Place & Precast) | C22: Most linked Ledger rows are in CWP 03 (6 of 9) — Inferred | D22: Approve by 2023-04-01 (CWP 03 first work, Inferred) | E22: 03-P01 | F22: SUB S1.1-01 | G22: Submittal | H22: Minimum structural shop drawings are concrete reinforcing (including wall elevations), mix designs, a slab-on-grade jointing plan and structural steel; deferred submittals, sealed by a Washington PE, are metal stairs & landings and the pre-engineered metal building for the Blower Building | I22: Shop drawings; Calculations / sealed design; Mix design; Plan / procedure | J22: Not stated | K22: n/a — submittal | L22: Contractor (submits per 01 33 00 — Inferred) | N22: S1.1 | O22: PROPOSED-BLOWER-BUILDING; PROPOSED-Blower-Building; PROPOSED-Blower-Building-Slab-and-Grade-Beams; PROPOSED-Blower-Pad; PROPOSED-Train-3-Concrete-Tank; PROPOSED-UV-Disinfection-Chamber-Basin; PROPOSED-Digester-Concrete-Tank; PROPOSED-Digester-Grating-Beam; PROPOSED-Drain-Pump-Station-Lid; PROPOSED-Steel-Stairs-Ladders-Platforms | P22: 1; 18 — Unresolved (see 04) | Q22: — | R22: Structural & Building | S22: Inferred | T22: Project_Wiki.md note S1.1 (Structural & Building): [plans_7 p.8, Submittals 4–5 — Verified-Visual] | U22: Requirement sentence taken verbatim from the note; Subtype, Timing, Acceptance and Responsible Party parsed from it by keyword (Merge, Inferred — check against the cited ¶). Linked Ledger rows: 9 (flag Y and sheet cited; linkage Inferred).
A23: CWP 03 | B23: Concrete (Cast-in-Place & Precast) | C23: Most linked Ledger rows are in CWP 03 (1 of 2) — Inferred | D23: Approve by 2023-04-01 (CWP 03 first work, Inferred) | E23: 03-P01 | F23: SUB S2.1-01 | G23: Submittal | H23: Detail 4 requires a hydrophilic waterstop (submit for approval), a grout surface per spec, and subgrade preparation per the structural notes and geotech report, and shows "guardrail, mechanical equipment, and ladders per civil" | I23: Certificates / reports | J23: Not stated | K23: n/a — submittal | L23: Contractor (submits per 01 33 00 — Inferred) | N23: S2.1 | O23: PROPOSED-Train-3-Concrete-Tank; PROPOSED-Train-3-Guardrail-and-Ladders | P23: 1; 18 — Unresolved (see 04) | Q23: — | R23: Structural & Building | S23: Inferred | T23: Project_Wiki.md note S2.1 (Structural & Building): [plans_8 p.1, Detail 4 — Verified-Visual] | U23: Requirement sentence taken verbatim from the note; Subtype, Timing, Acceptance and Responsible Party parsed from it by keyword (Merge, Inferred — check against the cited ¶). Linked Ledger rows: 2 (flag Y and sheet cited; linkage Inferred).
A24: CWP 03 | B24: Concrete (Cast-in-Place & Precast) | C24: Most linked Ledger rows are in CWP 03 (2 of 4) — Inferred | D24: Approve by 2023-04-01 (CWP 03 first work, Inferred) | E24: 03-P01 | F24: SUB S2.3-01 | G24: Submittal | H24: Details 5–7 cover slab control and construction joints (no more than 12'-0" o.c. each way), sleeved grade beam penetrations, and perimeter foundation drains of 4" rigid ABS perforated pipe or drain tile in drain rock that discharge by gravity or mechanical means, with a foundation drainage plan submitted to civil for review | I24: Plan / procedure | J24: Not stated | K24: n/a — submittal | L24: Contractor (submits per 01 33 00 — Inferred) | N24: S2.3 | O24: PROPOSED-BLOWER-BUILDING; PROPOSED-Blower-Building; PROPOSED-Blower-Building-Slab-and-Grade-Beams; PROPOSED-Blower-Pad; PROPOSED-Blower-Building-Foundation-Drains | P24: 1 | Q24: Reissued — Add. 4 p.9 governs | R24: Structural & Building | S24: Inferred | T24: Project_Wiki.md note S2.3 (Structural & Building): [plans_8 p.3; Add. 4 p.9 — Verified-Visual] | U24: Requirement sentence taken verbatim from the note; Subtype, Timing, Acceptance and Responsible Party parsed from it by keyword (Merge, Inferred — check against the cited ¶). Linked Ledger rows: 4 (flag Y and sheet cited; linkage Inferred).
A25: CWP 03 | B25: Concrete (Cast-in-Place & Precast) | C25: Most linked Ledger rows are in CWP 03 (4 of 4) — Inferred | D25: Approve by 2023-04-01 (CWP 03 first work, Inferred) | E25: 03-P01 | F25: SUB S2.4-01 | G25: Submittal | H25: Add. 4 requires the exterior of all precast concrete wet well and vault joints to be sealed with CANUSA-CPS WrapidSeal (manhole encapsulation system) or approved equal, installed per the manufacturer | I25: Calculations / sealed design | J25: Not stated | K25: n/a — submittal | L25: Contractor (submits per 01 33 00 — Inferred); also named: Manufacturer / supplier | N25: S2.4 | O25: PROPOSED-Drain-Pump-Station-Lid; PROPOSED-Drain-Pump-Station-Precast-Wet-Well; PROPOSED-Generator-Slab; PROPOSED-Flow-Splitter-Pad | P25: 1 | Q25: — | R25: Structural & Building | S25: Inferred | T25: Project_Wiki.md note S2.4 (Structural & Building): [Add. 4 p.1, Clarification 2 — Verified; Add. 4 governs] | U25: Requirement sentence taken verbatim from the note; Subtype, Timing, Acceptance and Responsible Party parsed from it by keyword (Merge, Inferred — check against the cited ¶). Linked Ledger rows: 4 (flag Y and sheet cited; linkage Inferred).
A26: CWP 03 | B26: Concrete (Cast-in-Place & Precast) | C26: Most linked Ledger rows are in CWP 03 (5 of 5) — Inferred | D26: Approve by 2023-04-01 (CWP 03 first work, Inferred) | E26: 03-P01 | F26: SUB S4.1-01 | G26: Submittal | H26: Details 1–7 are typical concrete details: wall-to-mat-slab reinforcing (hydrophilic waterstop for hydraulic structures, submit for approval), wall corner and intersection reinforcing, development and lap splice lengths, standard hooks, beam stirrups, and small and large penetrations | I26: General submittal | J26: Not stated | K26: n/a — submittal | L26: Contractor (submits per 01 33 00 — Inferred) | N26: S4.1 | O26: PROPOSED-Blower-Building-Slab-and-Grade-Beams; PROPOSED-Train-3-Concrete-Tank; PROPOSED-UV-Disinfection-Chamber-Basin; PROPOSED-Digester-Concrete-Tank; PROPOSED-Existing-Slab-Trench-Infill | P26: 1 | Q26: Reissued — Add. 4 p.10 governs; Detail 8 cited p.3 | R26: Structural & Building | S26: Inferred | T26: Project_Wiki.md note S4.1 (Structural & Building): [plans_8 p.5; Add. 4 p.10 — Verified-Visual] | U26: Requirement sentence taken verbatim from the note; Subtype, Timing, Acceptance and Responsible Party parsed from it by keyword (Merge, Inferred — check against the cited ¶). Linked Ledger rows: 5 (flag Y and sheet cited; linkage Inferred).
A27: CWP 03 | B27: Concrete (Cast-in-Place & Precast) | C27: Spec 03 30 00 | D27: Approve by 2023-04-01 (CWP 03 first work, Inferred) | E27: 03-P01 | F27: SUB 03 30 00-01 | G27: Submittal | H27: The Drawing Structural Notes take precedence over less specific spec requirements and set the mix designs and reinforcing, while WSDOT M41-10 (2022), WSDOT material sources, WSDOT-approved aggregate sources and WSDOT 9-04.2 joint sealant are incorporated by reference | I27: Mix design | J27: Not stated | K27: n/a — submittal | L27: Contractor (submits per 01 33 00 — Inferred) | M27: 03 30 00 | N27: A1.1; A1.2; S1.1; S2.3; S4.1; A1.3; S2.1; S2.2; S2.4 | O27: PROPOSED-Blower-Building-Slab-and-Grade-Beams; PROPOSED-Blower-Pad; PROPOSED-Train-3-Concrete-Tank; PROPOSED-UV-Disinfection-Chamber-Basin; PROPOSED-Digester-Concrete-Tank; PROPOSED-Drain-Pump-Station-Lid; PROPOSED-Generator-Slab; PROPOSED-Flow-Splitter-Pad; PROPOSED-Existing-Slab-Trench-Infill | P27: 1 | Q27: — | R27: Structural & Building | S27: Unresolved | T27: Project_Wiki.md note 03 30 00 (Structural & Building): [¶1.05 A, ¶2.03 A, ¶2.04 B–C, pp.172–175 — Verified; ¶1.04 A.1, ¶1.06 D.4, ¶2.04 A, ¶2.04 D — Unresolved: external reference, not staged] | U27: Requirement sentence taken verbatim from the note; Subtype, Timing, Acceptance and Responsible Party parsed from it by keyword (Merge, Inferred — check against the cited ¶). Linked Ledger rows: 9 (flag Y and section cited; linkage Inferred).
A28: CWP 03 | B28: Concrete (Cast-in-Place & Precast) | C28: Spec 03 30 00 | D28: Approve by 2023-04-01 (CWP 03 first work, Inferred) | E28: 03-P01 | F28: SUB 03 30 00-02 | G28: Submittal | H28: Submittals are ACI SP-66 shop drawings, mix designs 15 working days before use, material certificates, a PE-prepared hot and cold weather plan, joint layout plans (control joints no more than 30× slab thickness where not shown), and WA SE-sealed formwork plans and calculations for the "Clarifier, digester and chlorine contact basin structures" — names that do not all match the sheet titles | I28: Shop drawings; Calculations / sealed design; Mix design; Certificates / reports; Plan / procedure | J28: 15 working days before use; before use | K28: n/a — submittal | L28: Contractor (submits per 01 33 00 — Inferred) | M28: 03 30 00 | N28: A1.1; A1.2; S1.1; S2.3; S4.1; A1.3; S2.1; S2.2; S2.4 | O28: PROPOSED-Blower-Building-Slab-and-Grade-Beams; PROPOSED-Blower-Pad; PROPOSED-Train-3-Concrete-Tank; PROPOSED-UV-Disinfection-Chamber-Basin; PROPOSED-Digester-Concrete-Tank; PROPOSED-Drain-Pump-Station-Lid; PROPOSED-Generator-Slab; PROPOSED-Flow-Splitter-Pad; PROPOSED-Existing-Slab-Trench-Infill | P28: 1 | Q28: — | R28: Structural & Building | S28: Inferred | T28: Project_Wiki.md note 03 30 00 (Structural & Building): [¶1.06 A–G, p.173 — Verified; Issues, Missing information] | U28: Requirement sentence taken verbatim from the note; Subtype, Timing, Acceptance and Responsible Party parsed from it by keyword (Merge, Inferred — check against the cited ¶). Linked Ledger rows: 9 (flag Y and section cited; linkage Inferred).
A29: CWP 03 | B29: Concrete (Cast-in-Place & Precast) | C29: Spec 03 40 00 | D29: Approve by 2023-04-01 (CWP 03 first work, Inferred) | E29: 03-P01 | F29: SUB 03 40 00-01 | G29: Submittal | H29: Covers design, supply and installation of all precast concrete structures shown — vaults, top slabs and "the effluent wet well" — with WA-engineer-sealed shop drawings and calculations, mix designs 15 days ahead, material certificates, 5 years of NPCA certification, and Owner/Engineer plant inspection rights | I29: Shop drawings; Calculations / sealed design; Mix design; Certificates / reports | J29: 15 days ahead | K29: n/a — submittal | L29: Contractor (submits per 01 33 00 — Inferred); also named: Owner; Engineer | M29: 03 40 00 | N29: S2.4 | O29: PROPOSED-Drain-Pump-Station-Precast-Wet-Well; PROPOSED-2W-Pump-Station-Precast-Wet-Well; PROPOSED-Influent-Pump-Station-Precast-Wet-Well; PROPOSED-Influent-Pump-Station-Top-Slab; PROPOSED-Influent-Flow-Meter-Valve-Vault; PROPOSED-Effluent-Flow-Meter-Valve-Vault; PROPOSED-Plants-2-and-3-Flow-Meter-Vault; PROPOSED-Influent-Pump-Station-Meter-Vaults | P29: 1 | Q29: — | R29: Structural & Building | S29: Unresolved | T29: Project_Wiki.md note 03 40 00 (Structural & Building): [¶1.01 A, p.181; ¶1.06 A–F, ¶1.07, p.182 — Verified; WSDOT M41-10 references ¶1.04 C and ¶1.05 B — Unresolved: external reference, not staged] | U29: Requirement sentence taken verbatim from the note; Subtype, Timing, Acceptance and Responsible Party parsed from it by keyword (Merge, Inferred — check against the cited ¶). Linked Ledger rows: 8 (flag Y and section cited; linkage Inferred).
A30: CWP 05 | B30: Metals (Grating, Railings, Ladders, Stairs) | C30: Most linked Ledger rows are in CWP 05 (3 of 5) — Inferred | D30: Approve by 2023-04-01 (CWP 05 first work, Inferred) | E30: 05-P01 | F30: SUB S2.2-01 | G30: Submittal | H30: Sections A-A, B-B and C-C show #5 and #6 wall bars at 10"–12" o.c. (each face in the 12" walls, centered in the 8" walls) hooked 3" clear from bottom, a hydrophilic waterstop at all construction joints (submit for approval), an unreinforced sloped concrete topping per civil, subgrade preparation per the structural notes and geotech report, and "guardrail & ladders per civil" | I30: Certificates / reports | J30: Not stated | K30: n/a — submittal | L30: Contractor (submits per 01 33 00 — Inferred) | N30: S2.2 | O30: PROPOSED-UV-Disinfection-Chamber-Basin; PROPOSED-Digester-Concrete-Tank; PROPOSED-Digester-Grating-Beam; PROPOSED-UV-Digester-Grating; PROPOSED-UV-Digester-Guardrail-and-Ladders | P30: 1 | Q30: — | R30: Structural & Building | S30: Inferred | T30: Project_Wiki.md note S2.2 (Structural & Building): [plans_8 p.2, Details 2–4 — Verified-Visual] | U30: Requirement sentence taken verbatim from the note; Subtype, Timing, Acceptance and Responsible Party parsed from it by keyword (Merge, Inferred — check against the cited ¶). Linked Ledger rows: 5 (flag Y and sheet cited; linkage Inferred).
A31: CWP 05 | B31: Metals (Grating, Railings, Ladders, Stairs) | C31: Most linked Ledger rows are in CWP 05 (3 of 5) — Inferred | D31: Approve by 2023-04-01 (CWP 05 first work, Inferred) | E31: 05-P01 | F31: SUB S2.2-02 | G31: Submittal | H31: Aluminum solid plank grating per the specifications (submit for approval; attachment by manufacturer) bears on a continuous HDG 1/4" steel edge angle at wall tops (Detail 5) and a continuous HDG L3×3×1/4 with 5/8" drilled-and-epoxied anchors at 24" o.c. at wall faces (Detail 6); Detail 7 connects the HDG beam to the wall with HDG L4×4×3/8 angles, 3/4" A307 bolts and 5/8" epoxy anchors | I31: General submittal | J31: Not stated | K31: n/a — submittal | L31: Contractor (submits per 01 33 00 — Inferred); also named: Manufacturer / supplier | N31: S2.2 | O31: PROPOSED-UV-Disinfection-Chamber-Basin; PROPOSED-Digester-Concrete-Tank; PROPOSED-Digester-Grating-Beam; PROPOSED-UV-Digester-Grating; PROPOSED-UV-Digester-Guardrail-and-Ladders | P31: 1 | Q31: — | R31: Structural & Building | S31: Inferred | T31: Project_Wiki.md note S2.2 (Structural & Building): [plans_8 p.2, Details 5–7 — Verified-Visual] | U31: Requirement sentence taken verbatim from the note; Subtype, Timing, Acceptance and Responsible Party parsed from it by keyword (Merge, Inferred — check against the cited ¶). Linked Ledger rows: 5 (flag Y and sheet cited; linkage Inferred).
A32: CWP 05 | B32: Metals (Grating, Railings, Ladders, Stairs) | C32: Spec 05 50 00 | D32: Approve by 2023-04-01 (CWP 05 first work, Inferred) | E32: 05-P01 | F32: SUB 05 50 00-01 | G32: Submittal | H32: Submittals are shop drawings for all fabricated items, product data, nosing samples, PE qualification data, stainless mill certificates, paint compatibility certificates and welder certificates, with welding to AWS D1.1/D1.6 by state-licensed welders | I32: Shop drawings; Product data; Certificates / reports; Qualifications; Samples | J32: Not stated | K32: n/a — submittal | L32: Contractor (submits per 01 33 00 — Inferred) | M32: 05 50 00 | N32: S2.2; S1.1 | O32: PROPOSED-Digester-Grating-Beam | P32: 1 | Q32: — | R32: Structural & Building | S32: Inferred | T32: Project_Wiki.md note 05 50 00 (Structural & Building): [¶1.04, p.187; ¶1.05 B, p.187; ¶2.04 A, p.192 — Verified] | U32: Requirement sentence taken verbatim from the note; Subtype, Timing, Acceptance and Responsible Party parsed from it by keyword (Merge, Inferred — check against the cited ¶). Linked Ledger rows: 1 (flag Y and section cited; linkage Inferred).
A33: CWP 05 | B33: Metals (Grating, Railings, Ladders, Stairs) | C33: Spec 05 51 10 | D33: Approve by 2023-04-01 (CWP 05 first work, Inferred) | E33: 05-P01 | F33: SUB 05 51 10-01 | G33: Submittal | H33: Submittals are PE-sealed calculations and location-specific shop drawings (typical-detail sets are rejected), coordinated with the grating drawings and with aluminum handrails "as shown in the civil drawings" per 05 52 00 and 05 53 00 [¶1.03 A.1–3, p.200 — Verified], matching the deferred submittal for metal stairs and landings on S1.1 | I33: Shop drawings; Calculations / sealed design | J33: Not stated | K33: n/a — submittal | L33: Contractor (submits per 01 33 00 — Inferred) | M33: 05 51 10 | N33: S2.1; S2.2; S1.1 | O33: PROPOSED-Train-3-Guardrail-and-Ladders; PROPOSED-UV-Digester-Guardrail-and-Ladders; PROPOSED-Steel-Stairs-Ladders-Platforms | P33: 1; 18 — Unresolved (see 04) | Q33: — | R33: Structural & Building | S33: Inferred | T33: Project_Wiki.md note 05 51 10 (Structural & Building): [plans_7 p.8 — Verified-Visual] | U33: Requirement sentence taken verbatim from the note; Subtype, Timing, Acceptance and Responsible Party parsed from it by keyword (Merge, Inferred — check against the cited ¶). Linked Ledger rows: 3 (flag Y and section cited; linkage Inferred).
A34: CWP 05 | B34: Metals (Grating, Railings, Ladders, Stairs) | C34: Spec 05 51 10 | D34: Approve by 2023-04-01 (CWP 05 first work, Inferred) | E34: 05-P01 | F34: SUB 05 51 10-02 | G34: Submittal | H34: Unless shown otherwise, stairs use 7" risers, 11" treads and 1" nosing with 4'-0" min. clear width, access ladders have 3'-0" min. clear width, and field welding needs written approval at shop drawing review | I34: Shop drawings | J34: Not stated | K34: n/a — submittal | L34: Contractor (submits per 01 33 00 — Inferred) | M34: 05 51 10 | N34: S2.1; S2.2; S1.1 | O34: PROPOSED-Train-3-Guardrail-and-Ladders; PROPOSED-UV-Digester-Guardrail-and-Ladders; PROPOSED-Steel-Stairs-Ladders-Platforms | P34: 1; 18 — Unresolved (see 04) | Q34: — | R34: Structural & Building | S34: Inferred | T34: Project_Wiki.md note 05 51 10 (Structural & Building): [¶2.04, p.201; ¶3.01 D, p.202 — Verified] | U34: Requirement sentence taken verbatim from the note; Subtype, Timing, Acceptance and Responsible Party parsed from it by keyword (Merge, Inferred — check against the cited ¶). Linked Ledger rows: 3 (flag Y and section cited; linkage Inferred).
A35: CWP 05 | B35: Metals (Grating, Railings, Ladders, Stairs) | C35: Spec 05 52 00 | D35: Approve by 2023-04-01 (CWP 05 first work, Inferred) | E35: 05-P01 | F35: SUB 05 52 00-01 | G35: Submittal | H35: Submittals are shop drawings with a dimensional layout, the manufacturer's assembly and installation instructions, and calculations sealed by a Washington State registered structural engineer; partial or unsealed submittals are rejected | I35: Shop drawings; Calculations / sealed design | J35: Not stated | K35: n/a — submittal | L35: Contractor (submits per 01 33 00 — Inferred); also named: Manufacturer / supplier | M35: 05 52 00 | N35: S2.1; S2.2; S1.1 | O35: PROPOSED-Train-3-Guardrail-and-Ladders; PROPOSED-UV-Digester-Guardrail-and-Ladders; PROPOSED-Steel-Stairs-Ladders-Platforms | P35: 1; 18 — Unresolved (see 04) | Q35: — | R35: Structural & Building | S35: Inferred | T35: Project_Wiki.md note 05 52 00 (Structural & Building): [¶1.02 A–B, p.203 — Verified] | U35: Requirement sentence taken verbatim from the note; Subtype, Timing, Acceptance and Responsible Party parsed from it by keyword (Merge, Inferred — check against the cited ¶). Linked Ledger rows: 3 (flag Y and section cited; linkage Inferred).
A36: CWP 05 | B36: Metals (Grating, Railings, Ladders, Stairs) | C36: Spec 05 53 00 | D36: Approve by 2023-04-01 (CWP 05 first work, Inferred) | E36: 05-P01 | F36: SUB 05 53 00-01 | G36: Submittal | H36: Scope is aluminum grating set in pultruded vinyl ester FRP embedment angles with an integral anchor, to the NAAMM Metal Bar Grating Manual, with shop drawings and manufacturer's instructions as the submittal (the paragraph asks for a "dimensional layout of all handrailing," as written) | I36: Shop drawings; O&M manual | J36: Not stated | K36: n/a — submittal | L36: Contractor (submits per 01 33 00 — Inferred); also named: Manufacturer / supplier | M36: 05 53 00 | N36: S2.2; S1.1 | O36: PROPOSED-UV-Digester-Grating; PROPOSED-Steel-Stairs-Ladders-Platforms | P36: 1; 18 — Unresolved (see 04) | Q36: — | R36: Structural & Building | S36: Inferred | T36: Project_Wiki.md note 05 53 00 (Structural & Building): [¶1.01 A, ¶1.02 A, ¶1.03 A, p.205 — Verified] | U36: Requirement sentence taken verbatim from the note; Subtype, Timing, Acceptance and Responsible Party parsed from it by keyword (Merge, Inferred — check against the cited ¶). Linked Ledger rows: 2 (flag Y and section cited; linkage Inferred).
A37: CWP 06 | B37: Wood, Plastics & Composites | C37: Spec 06 20 00 | D37: No scheduled work | F37: SUB 06 20 00-01 | G37: Submittal | H37: Covers finish carpentry to AWI Quality Standards (Section 300, Custom Grade), APA and PS-1, with shop drawings and finish samples as submittals | I37: Shop drawings; Samples | J37: Not stated | K37: n/a — submittal | L37: Contractor (submits per 01 33 00 — Inferred) | M37: 06 20 00 | O37: None linked | P37: Not stated | Q37: — | R37: Structural & Building | S37: Verified | T37: Project_Wiki.md note 06 20 00 (Structural & Building): [¶1.1–1.3, p.207; ¶2.2 A, p.208 — Verified] | U37: Requirement sentence taken verbatim from the note; Subtype, Timing, Acceptance and Responsible Party parsed from it by keyword (Merge, Inferred — check against the cited ¶). Linked Ledger rows: 0 (flag Y and section cited; linkage Inferred).
A38: CWP 06 | B38: Wood, Plastics & Composites | C38: Spec 06 20 00 | D38: No scheduled work | F38: SUB 06 20 00-02 | G38: Submittal | H38: Execution covers coped and mitered trim, 45° splices, a sealed 1/8" gap at exterior trim ends, and installation of finish hardware and miscellaneous items on solid backing | I38: Calculations / sealed design | J38: Not stated | K38: n/a — submittal | L38: Contractor (submits per 01 33 00 — Inferred) | M38: 06 20 00 | O38: None linked | P38: Not stated | Q38: — | R38: Structural & Building | S38: Verified | T38: Project_Wiki.md note 06 20 00 (Structural & Building): [¶3.1 A–I, p.208 — Verified] | U38: Requirement sentence taken verbatim from the note; Subtype, Timing, Acceptance and Responsible Party parsed from it by keyword (Merge, Inferred — check against the cited ¶). Linked Ledger rows: 0 (flag Y and section cited; linkage Inferred).
A39: CWP 07 | B39: Thermal & Moisture Protection | C39: Spec 07 20 00 | D39: No scheduled work | F39: SUB 07 20 00-01 | G39: Submittal | H39: Covers thermal insulation and vapor barrier in exterior roof and wall construction, installed by a metal building insulation installer with 3 years' experience; materials arrive with instructions and typical shop drawings, and the section has no separate submittal article | I39: Shop drawings; Qualifications | J39: Not stated | K39: n/a — submittal | L39: Contractor (submits per 01 33 00 — Inferred) | M39: 07 20 00 | N39: C6.4; C6.5; A1.1; A1.2; A1.3; S1.1; S2.3 | O39: PROPOSED-BLOWER-BUILDING; PROPOSED-Blower-Building | P39: 1 | Q39: — | R39: Structural & Building | S39: Inferred | T39: Project_Wiki.md note 07 20 00 (Structural & Building): [¶1.1 A, ¶1.2 A–B, p.209 — Verified] | U39: Requirement sentence taken verbatim from the note; Subtype, Timing, Acceptance and Responsible Party parsed from it by keyword (Merge, Inferred — check against the cited ¶). Linked Ledger rows: 1 (flag Y and section cited; linkage Inferred).
