Workbook

Sheet Tracker Summary
A1: Installation Tracker — Summary by CWP
B3: Status date | C3: 45000 | D3: Input — set to the reporting date. Default = Notice to Proceed (Mar 15, 2023); no actual progress is entered in this sample.
A5: CWP | B5: Name | C5: Items | D5: Weight | E5: Planned % | F5: Earned % | G5: Variance | H5: Not started | I5: On track | J5: Behind | K5: Overdue | L5: Complete | M5: Planned start | N5: Planned finish
A6: CWP 01 | B6: General Requirements & Temporary Works | C6: =COUNTIFS(Tracker!$A$5:$A$467,"Item",Tracker!$B$5:$B$467,$A6) -> 12 | D6: =SUMIFS(Tracker!$O$5:$O$467,Tracker!$A$5:$A$467,"Item",Tracker!$B$5:$B$467,$A6) -> 12 | E6: =IFERROR(SUMPRODUCT((Tracker!$A$5:$A$467="Item")*(Tracker!$B$5:$B$467=$A6)*Tracker!$O$5:$O$467*Tracker!$Q$5:$Q$467)/D6,0) -> 0 | F6: =IFERROR(SUMPRODUCT((Tracker!$A$5:$A$467="Item")*(Tracker!$B$5:$B$467=$A6)*Tracker!$O$5:$O$467*Tracker!$P$5:$P$467)/D6,0) -> 0 | G6: =F6-E6 -> 0 | H6: =COUNTIFS(Tracker!$A$5:$A$467,"Item",Tracker!$B$5:$B$467,$A6,Tracker!$S$5:$S$467,"Not started") -> 4 | I6: =COUNTIFS(Tracker!$A$5:$A$467,"Item",Tracker!$B$5:$B$467,$A6,Tracker!$S$5:$S$467,"On track") -> 8 | J6: =COUNTIFS(Tracker!$A$5:$A$467,"Item",Tracker!$B$5:$B$467,$A6,Tracker!$S$5:$S$467,"Behind") -> 0 | K6: =COUNTIFS(Tracker!$A$5:$A$467,"Item",Tracker!$B$5:$B$467,$A6,Tracker!$S$5:$S$467,"Overdue") -> 0 | L6: =COUNTIFS(Tracker!$A$5:$A$467,"Item",Tracker!$B$5:$B$467,$A6,Tracker!$S$5:$S$467,"Complete") -> 0 | M6: =_xlfn.MINIFS(Tracker!$H$5:$H$467,Tracker!$A$5:$A$467,"Item",Tracker!$B$5:$B$467,$A6) -> 45000 | N6: =_xlfn.MAXIFS(Tracker!$I$5:$I$467,Tracker!$A$5:$A$467,"Item",Tracker!$B$5:$B$467,$A6) -> 45581
A7: CWP 02 | B7: Demolition & Existing Conditions | C7: =COUNTIFS(Tracker!$A$5:$A$467,"Item",Tracker!$B$5:$B$467,$A7) -> 21 | D7: =SUMIFS(Tracker!$O$5:$O$467,Tracker!$A$5:$A$467,"Item",Tracker!$B$5:$B$467,$A7) -> 21 | E7: =IFERROR(SUMPRODUCT((Tracker!$A$5:$A$467="Item")*(Tracker!$B$5:$B$467=$A7)*Tracker!$O$5:$O$467*Tracker!$Q$5:$Q$467)/D7,0) -> 0 | F7: =IFERROR(SUMPRODUCT((Tracker!$A$5:$A$467="Item")*(Tracker!$B$5:$B$467=$A7)*Tracker!$O$5:$O$467*Tracker!$P$5:$P$467)/D7,0) -> 0 | G7: =F7-E7 -> 0 | H7: =COUNTIFS(Tracker!$A$5:$A$467,"Item",Tracker!$B$5:$B$467,$A7,Tracker!$S$5:$S$467,"Not started") -> 21 | I7: =COUNTIFS(Tracker!$A$5:$A$467,"Item",Tracker!$B$5:$B$467,$A7,Tracker!$S$5:$S$467,"On track") -> 0 | J7: =COUNTIFS(Tracker!$A$5:$A$467,"Item",Tracker!$B$5:$B$467,$A7,Tracker!$S$5:$S$467,"Behind") -> 0 | K7: =COUNTIFS(Tracker!$A$5:$A$467,"Item",Tracker!$B$5:$B$467,$A7,Tracker!$S$5:$S$467,"Overdue") -> 0 | L7: =COUNTIFS(Tracker!$A$5:$A$467,"Item",Tracker!$B$5:$B$467,$A7,Tracker!$S$5:$S$467,"Complete") -> 0 | M7: =_xlfn.MINIFS(Tracker!$H$5:$H$467,Tracker!$A$5:$A$467,"Item",Tracker!$B$5:$B$467,$A7) -> 45017 | N7: =_xlfn.MAXIFS(Tracker!$I$5:$I$467,Tracker!$A$5:$A$467,"Item",Tracker!$B$5:$B$467,$A7) -> 45443
A8: CWP 03 | B8: Concrete (Cast-in-Place & Precast) | C8: =COUNTIFS(Tracker!$A$5:$A$467,"Item",Tracker!$B$5:$B$467,$A8) -> 30 | D8: =SUMIFS(Tracker!$O$5:$O$467,Tracker!$A$5:$A$467,"Item",Tracker!$B$5:$B$467,$A8) -> 30 | E8: =IFERROR(SUMPRODUCT((Tracker!$A$5:$A$467="Item")*(Tracker!$B$5:$B$467=$A8)*Tracker!$O$5:$O$467*Tracker!$Q$5:$Q$467)/D8,0) -> 0 | F8: =IFERROR(SUMPRODUCT((Tracker!$A$5:$A$467="Item")*(Tracker!$B$5:$B$467=$A8)*Tracker!$O$5:$O$467*Tracker!$P$5:$P$467)/D8,0) -> 0 | G8: =F8-E8 -> 0 | H8: =COUNTIFS(Tracker!$A$5:$A$467,"Item",Tracker!$B$5:$B$467,$A8,Tracker!$S$5:$S$467,"Not started") -> 30 | I8: =COUNTIFS(Tracker!$A$5:$A$467,"Item",Tracker!$B$5:$B$467,$A8,Tracker!$S$5:$S$467,"On track") -> 0 | J8: =COUNTIFS(Tracker!$A$5:$A$467,"Item",Tracker!$B$5:$B$467,$A8,Tracker!$S$5:$S$467,"Behind") -> 0 | K8: =COUNTIFS(Tracker!$A$5:$A$467,"Item",Tracker!$B$5:$B$467,$A8,Tracker!$S$5:$S$467,"Overdue") -> 0 | L8: =COUNTIFS(Tracker!$A$5:$A$467,"Item",Tracker!$B$5:$B$467,$A8,Tracker!$S$5:$S$467,"Complete") -> 0 | M8: =_xlfn.MINIFS(Tracker!$H$5:$H$467,Tracker!$A$5:$A$467,"Item",Tracker!$B$5:$B$467,$A8) -> 45017 | N8: =_xlfn.MAXIFS(Tracker!$I$5:$I$467,Tracker!$A$5:$A$467,"Item",Tracker!$B$5:$B$467,$A8) -> 45481
A9: CWP 05 | B9: Metals (Grating, Railings, Ladders, Stairs) | C9: =COUNTIFS(Tracker!$A$5:$A$467,"Item",Tracker!$B$5:$B$467,$A9) -> 6 | D9: =SUMIFS(Tracker!$O$5:$O$467,Tracker!$A$5:$A$467,"Item",Tracker!$B$5:$B$467,$A9) -> 6 | E9: =IFERROR(SUMPRODUCT((Tracker!$A$5:$A$467="Item")*(Tracker!$B$5:$B$467=$A9)*Tracker!$O$5:$O$467*Tracker!$Q$5:$Q$467)/D9,0) -> 0 | F9: =IFERROR(SUMPRODUCT((Tracker!$A$5:$A$467="Item")*(Tracker!$B$5:$B$467=$A9)*Tracker!$O$5:$O$467*Tracker!$P$5:$P$467)/D9,0) -> 0 | G9: =F9-E9 -> 0 | H9: =COUNTIFS(Tracker!$A$5:$A$467,"Item",Tracker!$B$5:$B$467,$A9,Tracker!$S$5:$S$467,"Not started") -> 6 | I9: =COUNTIFS(Tracker!$A$5:$A$467,"Item",Tracker!$B$5:$B$467,$A9,Tracker!$S$5:$S$467,"On track") -> 0 | J9: =COUNTIFS(Tracker!$A$5:$A$467,"Item",Tracker!$B$5:$B$467,$A9,Tracker!$S$5:$S$467,"Behind") -> 0 | K9: =COUNTIFS(Tracker!$A$5:$A$467,"Item",Tracker!$B$5:$B$467,$A9,Tracker!$S$5:$S$467,"Overdue") -> 0 | L9: =COUNTIFS(Tracker!$A$5:$A$467,"Item",Tracker!$B$5:$B$467,$A9,Tracker!$S$5:$S$467,"Complete") -> 0 | M9: =_xlfn.MINIFS(Tracker!$H$5:$H$467,Tracker!$A$5:$A$467,"Item",Tracker!$B$5:$B$467,$A9) -> 45017 | N9: =_xlfn.MAXIFS(Tracker!$I$5:$I$467,Tracker!$A$5:$A$467,"Item",Tracker!$B$5:$B$467,$A9) -> 45481
A10: CWP 08 | B10: Doors, Frames & Hardware | C10: =COUNTIFS(Tracker!$A$5:$A$467,"Item",Tracker!$B$5:$B$467,$A10) -> 4 | D10: =SUMIFS(Tracker!$O$5:$O$467,Tracker!$A$5:$A$467,"Item",Tracker!$B$5:$B$467,$A10) -> 4 | E10: =IFERROR(SUMPRODUCT((Tracker!$A$5:$A$467="Item")*(Tracker!$B$5:$B$467=$A10)*Tracker!$O$5:$O$467*Tracker!$Q$5:$Q$467)/D10,0) -> 0 | F10: =IFERROR(SUMPRODUCT((Tracker!$A$5:$A$467="Item")*(Tracker!$B$5:$B$467=$A10)*Tracker!$O$5:$O$467*Tracker!$P$5:$P$467)/D10,0) -> 0 | G10: =F10-E10 -> 0 | H10: =COUNTIFS(Tracker!$A$5:$A$467,"Item",Tracker!$B$5:$B$467,$A10,Tracker!$S$5:$S$467,"Not started") -> 4 | I10: =COUNTIFS(Tracker!$A$5:$A$467,"Item",Tracker!$B$5:$B$467,$A10,Tracker!$S$5:$S$467,"On track") -> 0 | J10: =COUNTIFS(Tracker!$A$5:$A$467,"Item",Tracker!$B$5:$B$467,$A10,Tracker!$S$5:$S$467,"Behind") -> 0 | K10: =COUNTIFS(Tracker!$A$5:$A$467,"Item",Tracker!$B$5:$B$467,$A10,Tracker!$S$5:$S$467,"Overdue") -> 0 | L10: =COUNTIFS(Tracker!$A$5:$A$467,"Item",Tracker!$B$5:$B$467,$A10,Tracker!$S$5:$S$467,"Complete") -> 0 | M10: =_xlfn.MINIFS(Tracker!$H$5:$H$467,Tracker!$A$5:$A$467,"Item",Tracker!$B$5:$B$467,$A10) -> 45017 | N10: =_xlfn.MAXIFS(Tracker!$I$5:$I$467,Tracker!$A$5:$A$467,"Item",Tracker!$B$5:$B$467,$A10) -> 45138
A11: CWP 09 | B11: Painting & Coatings | C11: =COUNTIFS(Tracker!$A$5:$A$467,"Item",Tracker!$B$5:$B$467,$A11) -> 1 | D11: =SUMIFS(Tracker!$O$5:$O$467,Tracker!$A$5:$A$467,"Item",Tracker!$B$5:$B$467,$A11) -> 1 | E11: =IFERROR(SUMPRODUCT((Tracker!$A$5:$A$467="Item")*(Tracker!$B$5:$B$467=$A11)*Tracker!$O$5:$O$467*Tracker!$Q$5:$Q$467)/D11,0) -> 0 | F11: =IFERROR(SUMPRODUCT((Tracker!$A$5:$A$467="Item")*(Tracker!$B$5:$B$467=$A11)*Tracker!$O$5:$O$467*Tracker!$P$5:$P$467)/D11,0) -> 0 | G11: =F11-E11 -> 0 | H11: =COUNTIFS(Tracker!$A$5:$A$467,"Item",Tracker!$B$5:$B$467,$A11,Tracker!$S$5:$S$467,"Not started") -> 1 | I11: =COUNTIFS(Tracker!$A$5:$A$467,"Item",Tracker!$B$5:$B$467,$A11,Tracker!$S$5:$S$467,"On track") -> 0 | J11: =COUNTIFS(Tracker!$A$5:$A$467,"Item",Tracker!$B$5:$B$467,$A11,Tracker!$S$5:$S$467,"Behind") -> 0 | K11: =COUNTIFS(Tracker!$A$5:$A$467,"Item",Tracker!$B$5:$B$467,$A11,Tracker!$S$5:$S$467,"Overdue") -> 0 | L11: =COUNTIFS(Tracker!$A$5:$A$467,"Item",Tracker!$B$5:$B$467,$A11,Tracker!$S$5:$S$467,"Complete") -> 0 | M11: =_xlfn.MINIFS(Tracker!$H$5:$H$467,Tracker!$A$5:$A$467,"Item",Tracker!$B$5:$B$467,$A11) -> 45078 | N11: =_xlfn.MAXIFS(Tracker!$I$5:$I$467,Tracker!$A$5:$A$467,"Item",Tracker!$B$5:$B$467,$A11) -> 45224
A12: CWP 10 | B12: Specialties | C12: =COUNTIFS(Tracker!$A$5:$A$467,"Item",Tracker!$B$5:$B$467,$A12) -> 3 | D12: =SUMIFS(Tracker!$O$5:$O$467,Tracker!$A$5:$A$467,"Item",Tracker!$B$5:$B$467,$A12) -> 3 | E12: =IFERROR(SUMPRODUCT((Tracker!$A$5:$A$467="Item")*(Tracker!$B$5:$B$467=$A12)*Tracker!$O$5:$O$467*Tracker!$Q$5:$Q$467)/D12,0) -> 0 | F12: =IFERROR(SUMPRODUCT((Tracker!$A$5:$A$467="Item")*(Tracker!$B$5:$B$467=$A12)*Tracker!$O$5:$O$467*Tracker!$P$5:$P$467)/D12,0) -> 0 | G12: =F12-E12 -> 0 | H12: =COUNTIFS(Tracker!$A$5:$A$467,"Item",Tracker!$B$5:$B$467,$A12,Tracker!$S$5:$S$467,"Not started") -> 3 | I12: =COUNTIFS(Tracker!$A$5:$A$467,"Item",Tracker!$B$5:$B$467,$A12,Tracker!$S$5:$S$467,"On track") -> 0 | J12: =COUNTIFS(Tracker!$A$5:$A$467,"Item",Tracker!$B$5:$B$467,$A12,Tracker!$S$5:$S$467,"Behind") -> 0 | K12: =COUNTIFS(Tracker!$A$5:$A$467,"Item",Tracker!$B$5:$B$467,$A12,Tracker!$S$5:$S$467,"Overdue") -> 0 | L12: =COUNTIFS(Tracker!$A$5:$A$467,"Item",Tracker!$B$5:$B$467,$A12,Tracker!$S$5:$S$467,"Complete") -> 0 | M12: =_xlfn.MINIFS(Tracker!$H$5:$H$467,Tracker!$A$5:$A$467,"Item",Tracker!$B$5:$B$467,$A12) -> 45017 | N12: =_xlfn.MAXIFS(Tracker!$I$5:$I$467,Tracker!$A$5:$A$467,"Item",Tracker!$B$5:$B$467,$A12) -> 45481
A13: CWP 13 | B13: Pre-Engineered Metal Building | C13: =COUNTIFS(Tracker!$A$5:$A$467,"Item",Tracker!$B$5:$B$467,$A13) -> 7 | D13: =SUMIFS(Tracker!$O$5:$O$467,Tracker!$A$5:$A$467,"Item",Tracker!$B$5:$B$467,$A13) -> 7 | E13: =IFERROR(SUMPRODUCT((Tracker!$A$5:$A$467="Item")*(Tracker!$B$5:$B$467=$A13)*Tracker!$O$5:$O$467*Tracker!$Q$5:$Q$467)/D13,0) -> 0 | F13: =IFERROR(SUMPRODUCT((Tracker!$A$5:$A$467="Item")*(Tracker!$B$5:$B$467=$A13)*Tracker!$O$5:$O$467*Tracker!$P$5:$P$467)/D13,0) -> 0 | G13: =F13-E13 -> 0 | H13: =COUNTIFS(Tracker!$A$5:$A$467,"Item",Tracker!$B$5:$B$467,$A13,Tracker!$S$5:$S$467,"Not started") -> 7 | I13: =COUNTIFS(Tracker!$A$5:$A$467,"Item",Tracker!$B$5:$B$467,$A13,Tracker!$S$5:$S$467,"On track") -> 0 | J13: =COUNTIFS(Tracker!$A$5:$A$467,"Item",Tracker!$B$5:$B$467,$A13,Tracker!$S$5:$S$467,"Behind") -> 0 | K13: =COUNTIFS(Tracker!$A$5:$A$467,"Item",Tracker!$B$5:$B$467,$A13,Tracker!$S$5:$S$467,"Overdue") -> 0 | L13: =COUNTIFS(Tracker!$A$5:$A$467,"Item",Tracker!$B$5:$B$467,$A13,Tracker!$S$5:$S$467,"Complete") -> 0 | M13: =_xlfn.MINIFS(Tracker!$H$5:$H$467,Tracker!$A$5:$A$467,"Item",Tracker!$B$5:$B$467,$A13) -> 45017 | N13: =_xlfn.MAXIFS(Tracker!$I$5:$I$467,Tracker!$A$5:$A$467,"Item",Tracker!$B$5:$B$467,$A13) -> 45443
A14: CWP 22 | B14: Plumbing & Process Pumps | C14: =COUNTIFS(Tracker!$A$5:$A$467,"Item",Tracker!$B$5:$B$467,$A14) -> 25 | D14: =SUMIFS(Tracker!$O$5:$O$467,Tracker!$A$5:$A$467,"Item",Tracker!$B$5:$B$467,$A14) -> 25 | E14: =IFERROR(SUMPRODUCT((Tracker!$A$5:$A$467="Item")*(Tracker!$B$5:$B$467=$A14)*Tracker!$O$5:$O$467*Tracker!$Q$5:$Q$467)/D14,0) -> 0 | F14: =IFERROR(SUMPRODUCT((Tracker!$A$5:$A$467="Item")*(Tracker!$B$5:$B$467=$A14)*Tracker!$O$5:$O$467*Tracker!$P$5:$P$467)/D14,0) -> 0 | G14: =F14-E14 -> 0 | H14: =COUNTIFS(Tracker!$A$5:$A$467,"Item",Tracker!$B$5:$B$467,$A14,Tracker!$S$5:$S$467,"Not started") -> 25 | I14: =COUNTIFS(Tracker!$A$5:$A$467,"Item",Tracker!$B$5:$B$467,$A14,Tracker!$S$5:$S$467,"On track") -> 0 | J14: =COUNTIFS(Tracker!$A$5:$A$467,"Item",Tracker!$B$5:$B$467,$A14,Tracker!$S$5:$S$467,"Behind") -> 0 | K14: =COUNTIFS(Tracker!$A$5:$A$467,"Item",Tracker!$B$5:$B$467,$A14,Tracker!$S$5:$S$467,"Overdue") -> 0 | L14: =COUNTIFS(Tracker!$A$5:$A$467,"Item",Tracker!$B$5:$B$467,$A14,Tracker!$S$5:$S$467,"Complete") -> 0 | M14: =_xlfn.MINIFS(Tracker!$H$5:$H$467,Tracker!$A$5:$A$467,"Item",Tracker!$B$5:$B$467,$A14) -> 45017 | N14: =_xlfn.MAXIFS(Tracker!$I$5:$I$467,Tracker!$A$5:$A$467,"Item",Tracker!$B$5:$B$467,$A14) -> 45331
A15: CWP 23 | B15: HVAC & Ventilation | C15: =COUNTIFS(Tracker!$A$5:$A$467,"Item",Tracker!$B$5:$B$467,$A15) -> 15 | D15: =SUMIFS(Tracker!$O$5:$O$467,Tracker!$A$5:$A$467,"Item",Tracker!$B$5:$B$467,$A15) -> 15 | E15: =IFERROR(SUMPRODUCT((Tracker!$A$5:$A$467="Item")*(Tracker!$B$5:$B$467=$A15)*Tracker!$O$5:$O$467*Tracker!$Q$5:$Q$467)/D15,0) -> 0 | F15: =IFERROR(SUMPRODUCT((Tracker!$A$5:$A$467="Item")*(Tracker!$B$5:$B$467=$A15)*Tracker!$O$5:$O$467*Tracker!$P$5:$P$467)/D15,0) -> 0 | G15: =F15-E15 -> 0 | H15: =COUNTIFS(Tracker!$A$5:$A$467,"Item",Tracker!$B$5:$B$467,$A15,Tracker!$S$5:$S$467,"Not started") -> 15 | I15: =COUNTIFS(Tracker!$A$5:$A$467,"Item",Tracker!$B$5:$B$467,$A15,Tracker!$S$5:$S$467,"On track") -> 0 | J15: =COUNTIFS(Tracker!$A$5:$A$467,"Item",Tracker!$B$5:$B$467,$A15,Tracker!$S$5:$S$467,"Behind") -> 0 | K15: =COUNTIFS(Tracker!$A$5:$A$467,"Item",Tracker!$B$5:$B$467,$A15,Tracker!$S$5:$S$467,"Overdue") -> 0 | L15: =COUNTIFS(Tracker!$A$5:$A$467,"Item",Tracker!$B$5:$B$467,$A15,Tracker!$S$5:$S$467,"Complete") -> 0 | M15: =_xlfn.MINIFS(Tracker!$H$5:$H$467,Tracker!$A$5:$A$467,"Item",Tracker!$B$5:$B$467,$A15) -> 45017 | N15: =_xlfn.MAXIFS(Tracker!$I$5:$I$467,Tracker!$A$5:$A$467,"Item",Tracker!$B$5:$B$467,$A15) -> 45331
A16: CWP 26 | B16: Electrical, Instrumentation & Controls | C16: =COUNTIFS(Tracker!$A$5:$A$467,"Item",Tracker!$B$5:$B$467,$A16) -> 103 | D16: =SUMIFS(Tracker!$O$5:$O$467,Tracker!$A$5:$A$467,"Item",Tracker!$B$5:$B$467,$A16) -> 103 | E16: =IFERROR(SUMPRODUCT((Tracker!$A$5:$A$467="Item")*(Tracker!$B$5:$B$467=$A16)*Tracker!$O$5:$O$467*Tracker!$Q$5:$Q$467)/D16,0) -> 0 | F16: =IFERROR(SUMPRODUCT((Tracker!$A$5:$A$467="Item")*(Tracker!$B$5:$B$467=$A16)*Tracker!$O$5:$O$467*Tracker!$P$5:$P$467)/D16,0) -> 0 | G16: =F16-E16 -> 0 | H16: =COUNTIFS(Tracker!$A$5:$A$467,"Item",Tracker!$B$5:$B$467,$A16,Tracker!$S$5:$S$467,"Not started") -> 101 | I16: =COUNTIFS(Tracker!$A$5:$A$467,"Item",Tracker!$B$5:$B$467,$A16,Tracker!$S$5:$S$467,"On track") -> 2 | J16: =COUNTIFS(Tracker!$A$5:$A$467,"Item",Tracker!$B$5:$B$467,$A16,Tracker!$S$5:$S$467,"Behind") -> 0 | K16: =COUNTIFS(Tracker!$A$5:$A$467,"Item",Tracker!$B$5:$B$467,$A16,Tracker!$S$5:$S$467,"Overdue") -> 0 | L16: =COUNTIFS(Tracker!$A$5:$A$467,"Item",Tracker!$B$5:$B$467,$A16,Tracker!$S$5:$S$467,"Complete") -> 0 | M16: =_xlfn.MINIFS(Tracker!$H$5:$H$467,Tracker!$A$5:$A$467,"Item",Tracker!$B$5:$B$467,$A16) -> 45000 | N16: =_xlfn.MAXIFS(Tracker!$I$5:$I$467,Tracker!$A$5:$A$467,"Item",Tracker!$B$5:$B$467,$A16) -> 45581
A17: CWP 31 | B17: Earthwork, Dewatering & Erosion Control | C17: =COUNTIFS(Tracker!$A$5:$A$467,"Item",Tracker!$B$5:$B$467,$A17) -> 19 | D17: =SUMIFS(Tracker!$O$5:$O$467,Tracker!$A$5:$A$467,"Item",Tracker!$B$5:$B$467,$A17) -> 19 | E17: =IFERROR(SUMPRODUCT((Tracker!$A$5:$A$467="Item")*(Tracker!$B$5:$B$467=$A17)*Tracker!$O$5:$O$467*Tracker!$Q$5:$Q$467)/D17,0) -> 0 | F17: =IFERROR(SUMPRODUCT((Tracker!$A$5:$A$467="Item")*(Tracker!$B$5:$B$467=$A17)*Tracker!$O$5:$O$467*Tracker!$P$5:$P$467)/D17,0) -> 0 | G17: =F17-E17 -> 0 | H17: =COUNTIFS(Tracker!$A$5:$A$467,"Item",Tracker!$B$5:$B$467,$A17,Tracker!$S$5:$S$467,"Not started") -> 5 | I17: =COUNTIFS(Tracker!$A$5:$A$467,"Item",Tracker!$B$5:$B$467,$A17,Tracker!$S$5:$S$467,"On track") -> 14 | J17: =COUNTIFS(Tracker!$A$5:$A$467,"Item",Tracker!$B$5:$B$467,$A17,Tracker!$S$5:$S$467,"Behind") -> 0 | K17: =COUNTIFS(Tracker!$A$5:$A$467,"Item",Tracker!$B$5:$B$467,$A17,Tracker!$S$5:$S$467,"Overdue") -> 0 | L17: =COUNTIFS(Tracker!$A$5:$A$467,"Item",Tracker!$B$5:$B$467,$A17,Tracker!$S$5:$S$467,"Complete") -> 0 | M17: =_xlfn.MINIFS(Tracker!$H$5:$H$467,Tracker!$A$5:$A$467,"Item",Tracker!$B$5:$B$467,$A17) -> 45000 | N17: =_xlfn.MAXIFS(Tracker!$I$5:$I$467,Tracker!$A$5:$A$467,"Item",Tracker!$B$5:$B$467,$A17) -> 45581
... A24: CWP 46 | B24: Treatment Equipment | C24: =COUNTIFS(Tracker!$A$5:$A$467,"Item",Tracker!$B$5:$B$467,$A24) -> 60 | D24: =SUMIFS(Tracker!$O$5:$O$467,Tracker!$A$5:$A$467,"Item",Tracker!$B$5:$B$467,$A24) -> 60 | E24: =IFERROR(SUMPRODUCT((Tracker!$A$5:$A$467="Item")*(Tracker!$B$5:$B$467=$A24)*Tracker!$O$5:$O$467*Tracker!$Q$5:$Q$467)/D24,0) -> 0 | F24: =IFERROR(SUMPRODUCT((Tracker!$A$5:$A$467="Item")*(Tracker!$B$5:$B$467=$A24)*Tracker!$O$5:$O$467*Tracker!$P$5:$P$467)/D24,0) -> 0 | G24: =F24-E24 -> 0 | H24: =COUNTIFS(Tracker!$A$5:$A$467,"Item",Tracker!$B$5:$B$467,$A24,Tracker!$S$5:$S$467,"Not started") -> 60 | I24: =COUNTIFS(Tracker!$A$5:$A$467,"Item",Tracker!$B$5:$B$467,$A24,Tracker!$S$5:$S$467,"On track") -> 0 | J24: =COUNTIFS(Tracker!$A$5:$A$467,"Item",Tracker!$B$5:$B$467,$A24,Tracker!$S$5:$S$467,"Behind") -> 0 | K24: =COUNTIFS(Tracker!$A$5:$A$467,"Item",Tracker!$B$5:$B$467,$A24,Tracker!$S$5:$S$467,"Overdue") -> 0 | L24: =COUNTIFS(Tracker!$A$5:$A$467,"Item",Tracker!$B$5:$B$467,$A24,Tracker!$S$5:$S$467,"Complete") -> 0 | M24: =_xlfn.MINIFS(Tracker!$H$5:$H$467,Tracker!$A$5:$A$467,"Item",Tracker!$B$5:$B$467,$A24) -> 45017 | N24: =_xlfn.MAXIFS(Tracker!$I$5:$I$467,Tracker!$A$5:$A$467,"Item",Tracker!$B$5:$B$467,$A24) -> 45481
A25: Total | C25: =SUM(C6:C24) -> 444 | D25: =SUM(D6:D24) -> 444 | E25: =IFERROR(SUMPRODUCT(D6:D24,E6:E24)/D25,0) -> 0 | F25: =IFERROR(SUMPRODUCT(D6:D24,F6:F24)/D25,0) -> 0 | G25: =F25-E25 -> 0 | H25: =SUM(H6:H24) -> 419 | I25: =SUM(I6:I24) -> 25 | J25: =SUM(J6:J24) -> 0 | K25: =SUM(K6:K24) -> 0 | L25: =SUM(L6:L24) -> 0 | M25: =MIN(M6:M24) -> 45000 | N25: =MAX(N6:N24) -> 45581

Sheet Tracker
A1: Eastsound WWTP Upgrade Phase I — Installation Tracker by CWP (proof of concept)
A2: Blue cells are inputs (dates or N/A). Planned dates come from the Schedule tab; progress uses the Rules of Credit tab; status date is on Tracker Summary. Rows sharing an item with another row are listed in 'Also tracked as' — update one of them.
A4: Row | B4: CWP | C4: Tag | D4: Item | E4: Area/Building | F4: Work type | G4: Schedule activity ID | H4: Planned start | I4: Planned finish | J4: Submittal approved | K4: On site / ready | L4: Installed / removed | M4: Tested / inspected | N4: Turned over / closed | O4: Weight | P4: Earned % | Q4: Planned % | R4: Variance | S4: Flag | T4: Remarks | U4: Schedule activity | V4: Submittal approve-by | W4: Submittal req | X4: Testing req | Y4: Submittal lines | Z4: ITP lines | AA4: Also tracked as (same item) | AB4: Open exceptions | AC4: Ledger tag level | AD4: Bid item | AE4: Drawing sheets | AF4: Spec sections | AG4: Wiki note(s) | AH4: Lane
A5: Section | B5: CWP 01 | C5: General Requirements & Temporary Works | D5: =COUNTIF(A6:A17,"Item")&" items · "&COUNTIF(S6:S17,"Overdue")&" overdue · "&COUNTIF(S6:S17,"Complete")&" complete" -> 12 items · 0 overdue · 0 complete | H5: =MIN(H6:H17) -> 45000 | I5: =MAX(I6:I17) -> 45581 | O5: =SUM(O6:O17) -> 12 | P5: =IFERROR(SUMPRODUCT(O6:O17,P6:P17)/SUM(O6:O17),0) -> 0 | Q5: =IFERROR(SUMPRODUCT(O6:O17,Q6:Q17)/SUM(O6:O17),0) -> 0 | R5: =P5-Q5 -> 0
A6: Item | B6: CWP 01 | C6: PROPOSED-Off-site staging area | D6: Contractor staging area off Mt Baker Road, with vehicle path to the project site | E6: Site (off-site staging) | F6: Temporary | G6: 01-C02 | H6: =IFERROR(INDEX(Schedule!$E$2:$E$147,MATCH($G6,Schedule!$A$2:$A$147,0)),"") -> 45000 | I6: =IFERROR(INDEX(Schedule!$F$2:$F$147,MATCH($G6,Schedule!$A$2:$A$147,0)),"") -> 45581 | O6: 1 | P6: =IFERROR((IF(OR(ISNUMBER(J6),UPPER(TRIM(J6))="N/A"),1,0)*IF($W6="N",0,INDEX('Rules of Credit'!$B$5:$F$8,MATCH($F6,'Rules of Credit'!$A$5:$A$8,0),1))+IF(OR(ISNUMBER(K6),UPPER(TRIM(K6))="N/A"),1,0)*INDEX('Rules of Credit'!$B$5:$F$8,MATCH($F6,'Rules of Credit'!$A$5:$A$8,0),2)+IF(OR(ISNUMBER(L6),UPPER(TRIM(L6))="N/A"),1,0)*INDEX('Rules of Credit'!$B$5:$F$8,MATCH($F6,'Rules of Credit'!$A$5:$A$8,0),3)+IF(OR(ISNUMBER(M6),UPPER(TRIM(M6))="N/A"),1,0)*IF($X6="N",0,INDEX('Rules of Credit'!$B$5:$F$8,MATCH($F6,'Rules of Credit'!$A$5:$A$8,0),4))+IF(OR(ISNUMBER(N6),UPPER(TRIM(N6))="N/A"),1,0)*INDEX('Rules of Credit'!$B$5:$F$8,MATCH($F6,'Rules of Credit'!$A$5:$A$8,0),5))/(IF($W6="N",0,INDEX('Rules of Credit'!$B$5:$F$8,MATCH($F6,'Rules of Credit'!$A$5:$A$8,0),1))+INDEX('Rules of Credit'!$B$5:$F$8,MATCH($F6,'Rules of Credit'!$A$5:$A$8,0),2)+INDEX('Rules of Credit'!$B$5:$F$8,MATCH($F6,'Rules of Credit'!$A$5:$A$8,0),3)+IF($X6="N",0,INDEX('Rules of Credit'!$B$5:$F$8,MATCH($F6,'Rules of Credit'!$A$5:$A$8,0),4))+INDEX('Rules of Credit'!$B$5:$F$8,MATCH($F6,'Rules of Credit'!$A$5:$A$8,0),5)),0) -> 0 | Q6: =IF(OR($H6="",$I6=""),0,IF('Tracker Summary'!$C$3<$H6,0,IF('Tracker Summary'!$C$3>=$I6,1,('Tracker Summary'!$C$3-$H6)/($I6-$H6+1)))) -> 0 | R6: =P6-Q6 -> 0 | S6: =IF($I6="","Not scheduled",IF(P6>=1,"Complete",IF('Tracker Summary'!$C$3>$I6,"Overdue",IF(P6-Q6<-0.1,"Behind",IF(AND(P6=0,'Tracker Summary'!$C$3<$H6),"Not started","On track"))))) -> On track | U6: =IFERROR(INDEX(Schedule!$D$2:$D$147,MATCH($G6,Schedule!$A$2:$A$147,0)),"") -> General Requirements & Temporary Works — Temporary facilities and controls | V6: =IFERROR(INDEX(Schedule!$F$2:$F$147,MATCH("01-P01",Schedule!$A$2:$A$147,0)),"") -> 44999 | W6: N | X6: N | Y6: 0 | Z6: 0 | AC6: Inferred | AD6: 1 | AE6: C0.6 | AG6: C0.6 | AH6: Civil & Site
A7: Item | B7: CWP 01 | C7: PROPOSED-Temporary construction sign | D7: Temporary construction sign, 4 x 8 ft plywood, Ecology and CDBG Commerce requirements | E7: Site | F7: Temporary | G7: 01-C02 | H7: =IFERROR(INDEX(Schedule!$E$2:$E$147,MATCH($G7,Schedule!$A$2:$A$147,0)),"") -> 45000 | I7: =IFERROR(INDEX(Schedule!$F$2:$F$147,MATCH($G7,Schedule!$A$2:$A$147,0)),"") -> 45581 | O7: 1 | P7: =IFERROR((IF(OR(ISNUMBER(J7),UPPER(TRIM(J7))="N/A"),1,0)*IF($W7="N",0,INDEX('Rules of Credit'!$B$5:$F$8,MATCH($F7,'Rules of Credit'!$A$5:$A$8,0),1))+IF(OR(ISNUMBER(K7),UPPER(TRIM(K7))="N/A"),1,0)*INDEX('Rules of Credit'!$B$5:$F$8,MATCH($F7,'Rules of Credit'!$A$5:$A$8,0),2)+IF(OR(ISNUMBER(L7),UPPER(TRIM(L7))="N/A"),1,0)*INDEX('Rules of Credit'!$B$5:$F$8,MATCH($F7,'Rules of Credit'!$A$5:$A$8,0),3)+IF(OR(ISNUMBER(M7),UPPER(TRIM(M7))="N/A"),1,0)*IF($X7="N",0,INDEX('Rules of Credit'!$B$5:$F$8,MATCH($F7,'Rules of Credit'!$A$5:$A$8,0),4))+IF(OR(ISNUMBER(N7),UPPER(TRIM(N7))="N/A"),1,0)*INDEX('Rules of Credit'!$B$5:$F$8,MATCH($F7,'Rules of Credit'!$A$5:$A$8,0),5))/(IF($W7="N",0,INDEX('Rules of Credit'!$B$5:$F$8,MATCH($F7,'Rules of Credit'!$A$5:$A$8,0),1))+INDEX('Rules of Credit'!$B$5:$F$8,MATCH($F7,'Rules of Credit'!$A$5:$A$8,0),2)+INDEX('Rules of Credit'!$B$5:$F$8,MATCH($F7,'Rules of Credit'!$A$5:$A$8,0),3)+IF($X7="N",0,INDEX('Rules of Credit'!$B$5:$F$8,MATCH($F7,'Rules of Credit'!$A$5:$A$8,0),4))+INDEX('Rules of Credit'!$B$5:$F$8,MATCH($F7,'Rules of Credit'!$A$5:$A$8,0),5)),0) -> 0 | Q7: =IF(OR($H7="",$I7=""),0,IF('Tracker Summary'!$C$3<$H7,0,IF('Tracker Summary'!$C$3>=$I7,1,('Tracker Summary'!$C$3-$H7)/($I7-$H7+1)))) -> 0 | R7: =P7-Q7 -> 0 | S7: =IF($I7="","Not scheduled",IF(P7>=1,"Complete",IF('Tracker Summary'!$C$3>$I7,"Overdue",IF(P7-Q7<-0.1,"Behind",IF(AND(P7=0,'Tracker Summary'!$C$3<$H7),"Not started","On track"))))) -> On track | U7: =IFERROR(INDEX(Schedule!$D$2:$D$147,MATCH($G7,Schedule!$A$2:$A$147,0)),"") -> General Requirements & Temporary Works — Temporary facilities and controls | V7: =IFERROR(INDEX(Schedule!$F$2:$F$147,MATCH("01-P01",Schedule!$A$2:$A$147,0)),"") -> 44999 | W7: Y | X7: N | Y7: 1 | Z7: 0 | AA7: PROPOSED-Funding-Recognition-Sign (Contract & General) | AB7: #72 | AC7: Inferred | AD7: 1 | AE7: — | AF7: 15 08 13 | AG7: 15 08 13 | AH7: Civil & Site
A8: Item | B8: CWP 01 | C8: PROPOSED-Funding-Recognition-Sign | D8: Funding recognition sign (Ecology financial assistance) | E8: Site | F8: Temporary | G8: 01-C02 | H8: =IFERROR(INDEX(Schedule!$E$2:$E$147,MATCH($G8,Schedule!$A$2:$A$147,0)),"") -> 45000 | I8: =IFERROR(INDEX(Schedule!$F$2:$F$147,MATCH($G8,Schedule!$A$2:$A$147,0)),"") -> 45581 | O8: 1 | P8: =IFERROR((IF(OR(ISNUMBER(J8),UPPER(TRIM(J8))="N/A"),1,0)*IF($W8="N",0,INDEX('Rules of Credit'!$B$5:$F$8,MATCH($F8,'Rules of Credit'!$A$5:$A$8,0),1))+IF(OR(ISNUMBER(K8),UPPER(TRIM(K8))="N/A"),1,0)*INDEX('Rules of Credit'!$B$5:$F$8,MATCH($F8,'Rules of Credit'!$A$5:$A$8,0),2)+IF(OR(ISNUMBER(L8),UPPER(TRIM(L8))="N/A"),1,0)*INDEX('Rules of Credit'!$B$5:$F$8,MATCH($F8,'Rules of Credit'!$A$5:$A$8,0),3)+IF(OR(ISNUMBER(M8),UPPER(TRIM(M8))="N/A"),1,0)*IF($X8="N",0,INDEX('Rules of Credit'!$B$5:$F$8,MATCH($F8,'Rules of Credit'!$A$5:$A$8,0),4))+IF(OR(ISNUMBER(N8),UPPER(TRIM(N8))="N/A"),1,0)*INDEX('Rules of Credit'!$B$5:$F$8,MATCH($F8,'Rules of Credit'!$A$5:$A$8,0),5))/(IF($W8="N",0,INDEX('Rules of Credit'!$B$5:$F$8,MATCH($F8,'Rules of Credit'!$A$5:$A$8,0),1))+INDEX('Rules of Credit'!$B$5:$F$8,MATCH($F8,'Rules of Credit'!$A$5:$A$8,0),2)+INDEX('Rules of Credit'!$B$5:$F$8,MATCH($F8,'Rules of Credit'!$A$5:$A$8,0),3)+IF($X8="N",0,INDEX('Rules of Credit'!$B$5:$F$8,MATCH($F8,'Rules of Credit'!$A$5:$A$8,0),4))+INDEX('Rules of Credit'!$B$5:$F$8,MATCH($F8,'Rules of Credit'!$A$5:$A$8,0),5)),0) -> 0 | Q8: =IF(OR($H8="",$I8=""),0,IF('Tracker Summary'!$C$3<$H8,0,IF('Tracker Summary'!$C$3>=$I8,1,('Tracker Summary'!$C$3-$H8)/($I8-$H8+1)))) -> 0 | R8: =P8-Q8 -> 0 | S8: =IF($I8="","Not scheduled",IF(P8>=1,"Complete",IF('Tracker Summary'!$C$3>$I8,"Overdue",IF(P8-Q8<-0.1,"Behind",IF(AND(P8=0,'Tracker Summary'!$C$3<$H8),"Not started","On track"))))) -> On track | U8: =IFERROR(INDEX(Schedule!$D$2:$D$147,MATCH($G8,Schedule!$A$2:$A$147,0)),"") -> General Requirements & Temporary Works — Temporary facilities and controls | V8: =IFERROR(INDEX(Schedule!$F$2:$F$147,MATCH("01-P01",Schedule!$A$2:$A$147,0)),"") -> 44999 | W8: N | X8: N | Y8: 0 | Z8: 0 | AA8: PROPOSED-Temporary construction sign (Civil & Site) | AB8: #72, #250 | AC8: Inferred | AD8: 1 | AF8: 00 53 00 | AG8: 00 53 00 | AH8: Contract & General
A9: Item | B9: CWP 01 | C9: PROPOSED-Temporary-Barriers | D9: Temporary barriers at openings and hazards (fencing, railing, barricades, steel plates, with warning signs or lights) | E9: Site | F9: Temporary | G9: 01-C02 | H9: =IFERROR(INDEX(Schedule!$E$2:$E$147,MATCH($G9,Schedule!$A$2:$A$147,0)),"") -> 45000 | I9: =IFERROR(INDEX(Schedule!$F$2:$F$147,MATCH($G9,Schedule!$A$2:$A$147,0)),"") -> 45581 | O9: 1 | P9: =IFERROR((IF(OR(ISNUMBER(J9),UPPER(TRIM(J9))="N/A"),1,0)*IF($W9="N",0,INDEX('Rules of Credit'!$B$5:$F$8,MATCH($F9,'Rules of Credit'!$A$5:$A$8,0),1))+IF(OR(ISNUMBER(K9),UPPER(TRIM(K9))="N/A"),1,0)*INDEX('Rules of Credit'!$B$5:$F$8,MATCH($F9,'Rules of Credit'!$A$5:$A$8,0),2)+IF(OR(ISNUMBER(L9),UPPER(TRIM(L9))="N/A"),1,0)*INDEX('Rules of Credit'!$B$5:$F$8,MATCH($F9,'Rules of Credit'!$A$5:$A$8,0),3)+IF(OR(ISNUMBER(M9),UPPER(TRIM(M9))="N/A"),1,0)*IF($X9="N",0,INDEX('Rules of Credit'!$B$5:$F$8,MATCH($F9,'Rules of Credit'!$A$5:$A$8,0),4))+IF(OR(ISNUMBER(N9),UPPER(TRIM(N9))="N/A"),1,0)*INDEX('Rules of Credit'!$B$5:$F$8,MATCH($F9,'Rules of Credit'!$A$5:$A$8,0),5))/(IF($W9="N",0,INDEX('Rules of Credit'!$B$5:$F$8,MATCH($F9,'Rules of Credit'!$A$5:$A$8,0),1))+INDEX('Rules of Credit'!$B$5:$F$8,MATCH($F9,'Rules of Credit'!$A$5:$A$8,0),2)+INDEX('Rules of Credit'!$B$5:$F$8,MATCH($F9,'Rules of Credit'!$A$5:$A$8,0),3)+IF($X9="N",0,INDEX('Rules of Credit'!$B$5:$F$8,MATCH($F9,'Rules of Credit'!$A$5:$A$8,0),4))+INDEX('Rules of Credit'!$B$5:$F$8,MATCH($F9,'Rules of Credit'!$A$5:$A$8,0),5)),0) -> 0 | Q9: =IF(OR($H9="",$I9=""),0,IF('Tracker Summary'!$C$3<$H9,0,IF('Tracker Summary'!$C$3>=$I9,1,('Tracker Summary'!$C$3-$H9)/($I9-$H9+1)))) -> 0 | R9: =P9-Q9 -> 0 | S9: =IF($I9="","Not scheduled",IF(P9>=1,"Complete",IF('Tracker Summary'!$C$3>$I9,"Overdue",IF(P9-Q9<-0.1,"Behind",IF(AND(P9=0,'Tracker Summary'!$C$3<$H9),"Not started","On track"))))) -> On track | U9: =IFERROR(INDEX(Schedule!$D$2:$D$147,MATCH($G9,Schedule!$A$2:$A$147,0)),"") -> General Requirements & Temporary Works — Temporary facilities and controls | V9: =IFERROR(INDEX(Schedule!$F$2:$F$147,MATCH("01-P01",Schedule!$A$2:$A$147,0)),"") -> 44999 | W9: N | X9: N | Y9: 0 | Z9: 0 | AC9: Inferred | AD9: 1 | AF9: 00 73 00; 01 50 00 | AG9: 00 73 00; 01 50 00 | AH9: Contract & General
A10: Item | B10: CWP 01 | C10: PROPOSED-Temporary-Pump-and-Process-Equipment | D10: Temporary pump and process equipment (removed at Final Completion) | E10: Not stated | F10: Temporary | G10: 01-C02 | H10: =IFERROR(INDEX(Schedule!$E$2:$E$147,MATCH($G10,Schedule!$A$2:$A$147,0)),"") -> 45000 | I10: =IFERROR(INDEX(Schedule!$F$2:$F$147,MATCH($G10,Schedule!$A$2:$A$147,0)),"") -> 45581 | O10: 1 | P10: =IFERROR((IF(OR(ISNUMBER(J10),UPPER(TRIM(J10))="N/A"),1,0)*IF($W10="N",0,INDEX('Rules of Credit'!$B$5:$F$8,MATCH($F10,'Rules of Credit'!$A$5:$A$8,0),1))+IF(OR(ISNUMBER(K10),UPPER(TRIM(K10))="N/A"),1,0)*INDEX('Rules of Credit'!$B$5:$F$8,MATCH($F10,'Rules of Credit'!$A$5:$A$8,0),2)+IF(OR(ISNUMBER(L10),UPPER(TRIM(L10))="N/A"),1,0)*INDEX('Rules of Credit'!$B$5:$F$8,MATCH($F10,'Rules of Credit'!$A$5:$A$8,0),3)+IF(OR(ISNUMBER(M10),UPPER(TRIM(M10))="N/A"),1,0)*IF($X10="N",0,INDEX('Rules of Credit'!$B$5:$F$8,MATCH($F10,'Rules of Credit'!$A$5:$A$8,0),4))+IF(OR(ISNUMBER(N10),UPPER(TRIM(N10))="N/A"),1,0)*INDEX('Rules of Credit'!$B$5:$F$8,MATCH($F10,'Rules of Credit'!$A$5:$A$8,0),5))/(IF($W10="N",0,INDEX('Rules of Credit'!$B$5:$F$8,MATCH($F10,'Rules of Credit'!$A$5:$A$8,0),1))+INDEX('Rules of Credit'!$B$5:$F$8,MATCH($F10,'Rules of Credit'!$A$5:$A$8,0),2)+INDEX('Rules of Credit'!$B$5:$F$8,MATCH($F10,'Rules of Credit'!$A$5:$A$8,0),3)+IF($X10="N",0,INDEX('Rules of Credit'!$B$5:$F$8,MATCH($F10,'Rules of Credit'!$A$5:$A$8,0),4))+INDEX('Rules of Credit'!$B$5:$F$8,MATCH($F10,'Rules of Credit'!$A$5:$A$8,0),5)),0) -> 0 | Q10: =IF(OR($H10="",$I10=""),0,IF('Tracker Summary'!$C$3<$H10,0,IF('Tracker Summary'!$C$3>=$I10,1,('Tracker Summary'!$C$3-$H10)/($I10-$H10+1)))) -> 0 | R10: =P10-Q10 -> 0 | S10: =IF($I10="","Not scheduled",IF(P10>=1,"Complete",IF('Tracker Summary'!$C$3>$I10,"Overdue",IF(P10-Q10<-0.1,"Behind",IF(AND(P10=0,'Tracker Summary'!$C$3<$H10),"Not started","On track"))))) -> On track | U10: =IFERROR(INDEX(Schedule!$D$2:$D$147,MATCH($G10,Schedule!$A$2:$A$147,0)),"") -> General Requirements & Temporary Works — Temporary facilities and controls | V10: =IFERROR(INDEX(Schedule!$F$2:$F$147,MATCH("01-P01",Schedule!$A$2:$A$147,0)),"") -> 44999 | W10: N | X10: N | Y10: 0 | Z10: 0 | AB10: #251 | AC10: Inferred | AD10: 1 | AF10: 00 73 00; 01 50 00; 01 70 00 | AG10: 00 73 00; 01 50 00; 01 70 00 | AH10: Contract & General
A11: Item | B11: CWP 01 | C11: PROPOSED-Contractor-Field-Office | D11: Contractor's field office (optional) | E11: Site | F11: Temporary | G11: 01-C02 | H11: =IFERROR(INDEX(Schedule!$E$2:$E$147,MATCH($G11,Schedule!$A$2:$A$147,0)),"") -> 45000 | I11: =IFERROR(INDEX(Schedule!$F$2:$F$147,MATCH($G11,Schedule!$A$2:$A$147,0)),"") -> 45581 | O11: 1 | P11: =IFERROR((IF(OR(ISNUMBER(J11),UPPER(TRIM(J11))="N/A"),1,0)*IF($W11="N",0,INDEX('Rules of Credit'!$B$5:$F$8,MATCH($F11,'Rules of Credit'!$A$5:$A$8,0),1))+IF(OR(ISNUMBER(K11),UPPER(TRIM(K11))="N/A"),1,0)*INDEX('Rules of Credit'!$B$5:$F$8,MATCH($F11,'Rules of Credit'!$A$5:$A$8,0),2)+IF(OR(ISNUMBER(L11),UPPER(TRIM(L11))="N/A"),1,0)*INDEX('Rules of Credit'!$B$5:$F$8,MATCH($F11,'Rules of Credit'!$A$5:$A$8,0),3)+IF(OR(ISNUMBER(M11),UPPER(TRIM(M11))="N/A"),1,0)*IF($X11="N",0,INDEX('Rules of Credit'!$B$5:$F$8,MATCH($F11,'Rules of Credit'!$A$5:$A$8,0),4))+IF(OR(ISNUMBER(N11),UPPER(TRIM(N11))="N/A"),1,0)*INDEX('Rules of Credit'!$B$5:$F$8,MATCH($F11,'Rules of Credit'!$A$5:$A$8,0),5))/(IF($W11="N",0,INDEX('Rules of Credit'!$B$5:$F$8,MATCH($F11,'Rules of Credit'!$A$5:$A$8,0),1))+INDEX('Rules of Credit'!$B$5:$F$8,MATCH($F11,'Rules of Credit'!$A$5:$A$8,0),2)+INDEX('Rules of Credit'!$B$5:$F$8,MATCH($F11,'Rules of Credit'!$A$5:$A$8,0),3)+IF($X11="N",0,INDEX('Rules of Credit'!$B$5:$F$8,MATCH($F11,'Rules of Credit'!$A$5:$A$8,0),4))+INDEX('Rules of Credit'!$B$5:$F$8,MATCH($F11,'Rules of Credit'!$A$5:$A$8,0),5)),0) -> 0 | Q11: =IF(OR($H11="",$I11=""),0,IF('Tracker Summary'!$C$3<$H11,0,IF('Tracker Summary'!$C$3>=$I11,1,('Tracker Summary'!$C$3-$H11)/($I11-$H11+1)))) -> 0 | R11: =P11-Q11 -> 0 | S11: =IF($I11="","Not scheduled",IF(P11>=1,"Complete",IF('Tracker Summary'!$C$3>$I11,"Overdue",IF(P11-Q11<-0.1,"Behind",IF(AND(P11=0,'Tracker Summary'!$C$3<$H11),"Not started","On track"))))) -> On track | U11: =IFERROR(INDEX(Schedule!$D$2:$D$147,MATCH($G11,Schedule!$A$2:$A$147,0)),"") -> General Requirements & Temporary Works — Temporary facilities and controls | V11: =IFERROR(INDEX(Schedule!$F$2:$F$147,MATCH("01-P01",Schedule!$A$2:$A$147,0)),"") -> 44999 | W11: N | X11: N | Y11: 0 | Z11: 0 | AC11: Unresolved | AD11: 1 | AF11: 01 50 00; 01 31 00 | AG11: 01 50 00; 01 31 00; CQA Plan | AH11: Contract & General
A12: Item | B12: CWP 01 | C12: PROPOSED-Temporary-Construction-Water-Connection | D12: Temporary metered construction water connection with backflow preventer (if agreed) | E12: Site | F12: Temporary | G12: 01-C02 | H12: =IFERROR(INDEX(Schedule!$E$2:$E$147,MATCH($G12,Schedule!$A$2:$A$147,0)),"") -> 45000 | I12: =IFERROR(INDEX(Schedule!$F$2:$F$147,MATCH($G12,Schedule!$A$2:$A$147,0)),"") -> 45581 | O12: 1 | P12: =IFERROR((IF(OR(ISNUMBER(J12),UPPER(TRIM(J12))="N/A"),1,0)*IF($W12="N",0,INDEX('Rules of Credit'!$B$5:$F$8,MATCH($F12,'Rules of Credit'!$A$5:$A$8,0),1))+IF(OR(ISNUMBER(K12),UPPER(TRIM(K12))="N/A"),1,0)*INDEX('Rules of Credit'!$B$5:$F$8,MATCH($F12,'Rules of Credit'!$A$5:$A$8,0),2)+IF(OR(ISNUMBER(L12),UPPER(TRIM(L12))="N/A"),1,0)*INDEX('Rules of Credit'!$B$5:$F$8,MATCH($F12,'Rules of Credit'!$A$5:$A$8,0),3)+IF(OR(ISNUMBER(M12),UPPER(TRIM(M12))="N/A"),1,0)*IF($X12="N",0,INDEX('Rules of Credit'!$B$5:$F$8,MATCH($F12,'Rules of Credit'!$A$5:$A$8,0),4))+IF(OR(ISNUMBER(N12),UPPER(TRIM(N12))="N/A"),1,0)*INDEX('Rules of Credit'!$B$5:$F$8,MATCH($F12,'Rules of Credit'!$A$5:$A$8,0),5))/(IF($W12="N",0,INDEX('Rules of Credit'!$B$5:$F$8,MATCH($F12,'Rules of Credit'!$A$5:$A$8,0),1))+INDEX('Rules of Credit'!$B$5:$F$8,MATCH($F12,'Rules of Credit'!$A$5:$A$8,0),2)+INDEX('Rules of Credit'!$B$5:$F$8,MATCH($F12,'Rules of Credit'!$A$5:$A$8,0),3)+IF($X12="N",0,INDEX('Rules of Credit'!$B$5:$F$8,MATCH($F12,'Rules of Credit'!$A$5:$A$8,0),4))+INDEX('Rules of Credit'!$B$5:$F$8,MATCH($F12,'Rules of Credit'!$A$5:$A$8,0),5)),0) -> 0 | Q12: =IF(OR($H12="",$I12=""),0,IF('Tracker Summary'!$C$3<$H12,0,IF('Tracker Summary'!$C$3>=$I12,1,('Tracker Summary'!$C$3-$H12)/($I12-$H12+1)))) -> 0 | R12: =P12-Q12 -> 0 | S12: =IF($I12="","Not scheduled",IF(P12>=1,"Complete",IF('Tracker Summary'!$C$3>$I12,"Overdue",IF(P12-Q12<-0.1,"Behind",IF(AND(P12=0,'Tracker Summary'!$C$3<$H12),"Not started","On track"))))) -> On track | U12: =IFERROR(INDEX(Schedule!$D$2:$D$147,MATCH($G12,Schedule!$A$2:$A$147,0)),"") -> General Requirements & Temporary Works — Temporary facilities and controls | V12: =IFERROR(INDEX(Schedule!$F$2:$F$147,MATCH("01-P01",Schedule!$A$2:$A$147,0)),"") -> 44999 | W12: N | X12: N | Y12: 0 | Z12: 0 | AC12: Unresolved | AD12: 1 | AF12: 01 50 00 | AG12: 01 50 00 | AH12: Contract & General
A13: Item | B13: CWP 01 | C13: PROPOSED-Temporary-Sanitary-Facilities | D13: Temporary restrooms (contract service allowed) | E13: Site | F13: Temporary | G13: 01-C02 | H13: =IFERROR(INDEX(Schedule!$E$2:$E$147,MATCH($G13,Schedule!$A$2:$A$147,0)),"") -> 45000 | I13: =IFERROR(INDEX(Schedule!$F$2:$F$147,MATCH($G13,Schedule!$A$2:$A$147,0)),"") -> 45581 | O13: 1 | P13: =IFERROR((IF(OR(ISNUMBER(J13),UPPER(TRIM(J13))="N/A"),1,0)*IF($W13="N",0,INDEX('Rules of Credit'!$B$5:$F$8,MATCH($F13,'Rules of Credit'!$A$5:$A$8,0),1))+IF(OR(ISNUMBER(K13),UPPER(TRIM(K13))="N/A"),1,0)*INDEX('Rules of Credit'!$B$5:$F$8,MATCH($F13,'Rules of Credit'!$A$5:$A$8,0),2)+IF(OR(ISNUMBER(L13),UPPER(TRIM(L13))="N/A"),1,0)*INDEX('Rules of Credit'!$B$5:$F$8,MATCH($F13,'Rules of Credit'!$A$5:$A$8,0),3)+IF(OR(ISNUMBER(M13),UPPER(TRIM(M13))="N/A"),1,0)*IF($X13="N",0,INDEX('Rules of Credit'!$B$5:$F$8,MATCH($F13,'Rules of Credit'!$A$5:$A$8,0),4))+IF(OR(ISNUMBER(N13),UPPER(TRIM(N13))="N/A"),1,0)*INDEX('Rules of Credit'!$B$5:$F$8,MATCH($F13,'Rules of Credit'!$A$5:$A$8,0),5))/(IF($W13="N",0,INDEX('Rules of Credit'!$B$5:$F$8,MATCH($F13,'Rules of Credit'!$A$5:$A$8,0),1))+INDEX('Rules of Credit'!$B$5:$F$8,MATCH($F13,'Rules of Credit'!$A$5:$A$8,0),2)+INDEX('Rules of Credit'!$B$5:$F$8,MATCH($F13,'Rules of Credit'!$A$5:$A$8,0),3)+IF($X13="N",0,INDEX('Rules of Credit'!$B$5:$F$8,MATCH($F13,'Rules of Credit'!$A$5:$A$8,0),4))+INDEX('Rules of Credit'!$B$5:$F$8,MATCH($F13,'Rules of Credit'!$A$5:$A$8,0),5)),0) -> 0 | Q13: =IF(OR($H13="",$I13=""),0,IF('Tracker Summary'!$C$3<$H13,0,IF('Tracker Summary'!$C$3>=$I13,1,('Tracker Summary'!$C$3-$H13)/($I13-$H13+1)))) -> 0 | R13: =P13-Q13 -> 0 | S13: =IF($I13="","Not scheduled",IF(P13>=1,"Complete",IF('Tracker Summary'!$C$3>$I13,"Overdue",IF(P13-Q13<-0.1,"Behind",IF(AND(P13=0,'Tracker Summary'!$C$3<$H13),"Not started","On track"))))) -> On track | U13: =IFERROR(INDEX(Schedule!$D$2:$D$147,MATCH($G13,Schedule!$A$2:$A$147,0)),"") -> General Requirements & Temporary Works — Temporary facilities and controls | V13: =IFERROR(INDEX(Schedule!$F$2:$F$147,MATCH("01-P01",Schedule!$A$2:$A$147,0)),"") -> 44999 | W13: N | X13: N | Y13: 0 | Z13: 0 | AC13: Unresolved | AD13: 1 | AF13: 01 50 00 | AG13: 01 50 00 | AH13: Contract & General
A14: Item | B14: CWP 01 | C14: PROPOSED-Temporary bypass pumping system | D14: Temporary bypass pumping, piping, holding tanks and storage | E14: Site | F14: Temporary | G14: 01-C01 | H14: =IFERROR(INDEX(Schedule!$E$2:$E$147,MATCH($G14,Schedule!$A$2:$A$147,0)),"") -> 45017 | I14: =IFERROR(INDEX(Schedule!$F$2:$F$147,MATCH($G14,Schedule!$A$2:$A$147,0)),"") -> 45210 | O14: 1 | P14: =IFERROR((IF(OR(ISNUMBER(J14),UPPER(TRIM(J14))="N/A"),1,0)*IF($W14="N",0,INDEX('Rules of Credit'!$B$5:$F$8,MATCH($F14,'Rules of Credit'!$A$5:$A$8,0),1))+IF(OR(ISNUMBER(K14),UPPER(TRIM(K14))="N/A"),1,0)*INDEX('Rules of Credit'!$B$5:$F$8,MATCH($F14,'Rules of Credit'!$A$5:$A$8,0),2)+IF(OR(ISNUMBER(L14),UPPER(TRIM(L14))="N/A"),1,0)*INDEX('Rules of Credit'!$B$5:$F$8,MATCH($F14,'Rules of Credit'!$A$5:$A$8,0),3)+IF(OR(ISNUMBER(M14),UPPER(TRIM(M14))="N/A"),1,0)*IF($X14="N",0,INDEX('Rules of Credit'!$B$5:$F$8,MATCH($F14,'Rules of Credit'!$A$5:$A$8,0),4))+IF(OR(ISNUMBER(N14),UPPER(TRIM(N14))="N/A"),1,0)*INDEX('Rules of Credit'!$B$5:$F$8,MATCH($F14,'Rules of Credit'!$A$5:$A$8,0),5))/(IF($W14="N",0,INDEX('Rules of Credit'!$B$5:$F$8,MATCH($F14,'Rules of Credit'!$A$5:$A$8,0),1))+INDEX('Rules of Credit'!$B$5:$F$8,MATCH($F14,'Rules of Credit'!$A$5:$A$8,0),2)+INDEX('Rules of Credit'!$B$5:$F$8,MATCH($F14,'Rules of Credit'!$A$5:$A$8,0),3)+IF($X14="N",0,INDEX('Rules of Credit'!$B$5:$F$8,MATCH($F14,'Rules of Credit'!$A$5:$A$8,0),4))+INDEX('Rules of Credit'!$B$5:$F$8,MATCH($F14,'Rules of Credit'!$A$5:$A$8,0),5)),0) -> 0 | Q14: =IF(OR($H14="",$I14=""),0,IF('Tracker Summary'!$C$3<$H14,0,IF('Tracker Summary'!$C$3>=$I14,1,('Tracker Summary'!$C$3-$H14)/($I14-$H14+1)))) -> 0 | R14: =P14-Q14 -> 0 | S14: =IF($I14="","Not scheduled",IF(P14>=1,"Complete",IF('Tracker Summary'!$C$3>$I14,"Overdue",IF(P14-Q14<-0.1,"Behind",IF(AND(P14=0,'Tracker Summary'!$C$3<$H14),"Not started","On track"))))) -> Not started | U14: =IFERROR(INDEX(Schedule!$D$2:$D$147,MATCH($G14,Schedule!$A$2:$A$147,0)),"") -> General Requirements & Temporary Works — Temporary bypass and interim effluent piping | V14: =IFERROR(INDEX(Schedule!$F$2:$F$147,MATCH("01-P01",Schedule!$A$2:$A$147,0)),"") -> 44999 | W14: N | X14: N | Y14: 0 | Z14: 0 | AA14: PROPOSED-Temporary-Bypass-Pipe (Contract & General); PROPOSED-Temporary-Bypass-Alarm-Monitoring (Contract & General); PROPOSED-Bypass-Pumping-System (Contract & General) | AB14: #68 | AC14: Inferred | AD14: 1 | AE14: G0.3; C0.5 | AG14: G0.3; C0.5; Appendix F | AH14: Civil & Site
A15: Item | B15: CWP 01 | C15: PROPOSED-Temporary-Bypass-Pipe | D15: Temporary bypass pipe (chlorine contact tank outlet to 8-inch plant outlet) | E15: Site | F15: Temporary | G15: 01-C01 | H15: =IFERROR(INDEX(Schedule!$E$2:$E$147,MATCH($G15,Schedule!$A$2:$A$147,0)),"") -> 45017 | I15: =IFERROR(INDEX(Schedule!$F$2:$F$147,MATCH($G15,Schedule!$A$2:$A$147,0)),"") -> 45210 | O15: 1 | P15: =IFERROR((IF(OR(ISNUMBER(J15),UPPER(TRIM(J15))="N/A"),1,0)*IF($W15="N",0,INDEX('Rules of Credit'!$B$5:$F$8,MATCH($F15,'Rules of Credit'!$A$5:$A$8,0),1))+IF(OR(ISNUMBER(K15),UPPER(TRIM(K15))="N/A"),1,0)*INDEX('Rules of Credit'!$B$5:$F$8,MATCH($F15,'Rules of Credit'!$A$5:$A$8,0),2)+IF(OR(ISNUMBER(L15),UPPER(TRIM(L15))="N/A"),1,0)*INDEX('Rules of Credit'!$B$5:$F$8,MATCH($F15,'Rules of Credit'!$A$5:$A$8,0),3)+IF(OR(ISNUMBER(M15),UPPER(TRIM(M15))="N/A"),1,0)*IF($X15="N",0,INDEX('Rules of Credit'!$B$5:$F$8,MATCH($F15,'Rules of Credit'!$A$5:$A$8,0),4))+IF(OR(ISNUMBER(N15),UPPER(TRIM(N15))="N/A"),1,0)*INDEX('Rules of Credit'!$B$5:$F$8,MATCH($F15,'Rules of Credit'!$A$5:$A$8,0),5))/(IF($W15="N",0,INDEX('Rules of Credit'!$B$5:$F$8,MATCH($F15,'Rules of Credit'!$A$5:$A$8,0),1))+INDEX('Rules of Credit'!$B$5:$F$8,MATCH($F15,'Rules of Credit'!$A$5:$A$8,0),2)+INDEX('Rules of Credit'!$B$5:$F$8,MATCH($F15,'Rules of Credit'!$A$5:$A$8,0),3)+IF($X15="N",0,INDEX('Rules of Credit'!$B$5:$F$8,MATCH($F15,'Rules of Credit'!$A$5:$A$8,0),4))+INDEX('Rules of Credit'!$B$5:$F$8,MATCH($F15,'Rules of Credit'!$A$5:$A$8,0),5)),0) -> 0 | Q15: =IF(OR($H15="",$I15=""),0,IF('Tracker Summary'!$C$3<$H15,0,IF('Tracker Summary'!$C$3>=$I15,1,('Tracker Summary'!$C$3-$H15)/($I15-$H15+1)))) -> 0 | R15: =P15-Q15 -> 0 | S15: =IF($I15="","Not scheduled",IF(P15>=1,"Complete",IF('Tracker Summary'!$C$3>$I15,"Overdue",IF(P15-Q15<-0.1,"Behind",IF(AND(P15=0,'Tracker Summary'!$C$3<$H15),"Not started","On track"))))) -> Not started | U15: =IFERROR(INDEX(Schedule!$D$2:$D$147,MATCH($G15,Schedule!$A$2:$A$147,0)),"") -> General Requirements & Temporary Works — Temporary bypass and interim effluent piping | V15: =IFERROR(INDEX(Schedule!$F$2:$F$147,MATCH("01-P01",Schedule!$A$2:$A$147,0)),"") -> 44999 | W15: N | X15: N | Y15: 0 | Z15: 0 | AA15: PROPOSED-Temporary bypass pumping system (Civil & Site) | AB15: #68, #250 | AC15: Inferred | AD15: 1 | AF15: 00 31 13 | AG15: 00 31 13 | AH15: Contract & General
A16: Item | B16: CWP 01 | C16: PROPOSED-Bypass-Pumping-System | D16: Bypass pumping systems (influent and effluent) for WWTP shutdowns | E16: Site | F16: Temporary | G16: 01-C01 | H16: =IFERROR(INDEX(Schedule!$E$2:$E$147,MATCH($G16,Schedule!$A$2:$A$147,0)),"") -> 45017 | I16: =IFERROR(INDEX(Schedule!$F$2:$F$147,MATCH($G16,Schedule!$A$2:$A$147,0)),"") -> 45210 | O16: 1 | P16: =IFERROR((IF(OR(ISNUMBER(J16),UPPER(TRIM(J16))="N/A"),1,0)*IF($W16="N",0,INDEX('Rules of Credit'!$B$5:$F$8,MATCH($F16,'Rules of Credit'!$A$5:$A$8,0),1))+IF(OR(ISNUMBER(K16),UPPER(TRIM(K16))="N/A"),1,0)*INDEX('Rules of Credit'!$B$5:$F$8,MATCH($F16,'Rules of Credit'!$A$5:$A$8,0),2)+IF(OR(ISNUMBER(L16),UPPER(TRIM(L16))="N/A"),1,0)*INDEX('Rules of Credit'!$B$5:$F$8,MATCH($F16,'Rules of Credit'!$A$5:$A$8,0),3)+IF(OR(ISNUMBER(M16),UPPER(TRIM(M16))="N/A"),1,0)*IF($X16="N",0,INDEX('Rules of Credit'!$B$5:$F$8,MATCH($F16,'Rules of Credit'!$A$5:$A$8,0),4))+IF(OR(ISNUMBER(N16),UPPER(TRIM(N16))="N/A"),1,0)*INDEX('Rules of Credit'!$B$5:$F$8,MATCH($F16,'Rules of Credit'!$A$5:$A$8,0),5))/(IF($W16="N",0,INDEX('Rules of Credit'!$B$5:$F$8,MATCH($F16,'Rules of Credit'!$A$5:$A$8,0),1))+INDEX('Rules of Credit'!$B$5:$F$8,MATCH($F16,'Rules of Credit'!$A$5:$A$8,0),2)+INDEX('Rules of Credit'!$B$5:$F$8,MATCH($F16,'Rules of Credit'!$A$5:$A$8,0),3)+IF($X16="N",0,INDEX('Rules of Credit'!$B$5:$F$8,MATCH($F16,'Rules of Credit'!$A$5:$A$8,0),4))+INDEX('Rules of Credit'!$B$5:$F$8,MATCH($F16,'Rules of Credit'!$A$5:$A$8,0),5)),0) -> 0 | Q16: =IF(OR($H16="",$I16=""),0,IF('Tracker Summary'!$C$3<$H16,0,IF('Tracker Summary'!$C$3>=$I16,1,('Tracker Summary'!$C$3-$H16)/($I16-$H16+1)))) -> 0 | R16: =P16-Q16 -> 0 | S16: =IF($I16="","Not scheduled",IF(P16>=1,"Complete",IF('Tracker Summary'!$C$3>$I16,"Overdue",IF(P16-Q16<-0.1,"Behind",IF(AND(P16=0,'Tracker Summary'!$C$3<$H16),"Not started","On track"))))) -> Not started | U16: =IFERROR(INDEX(Schedule!$D$2:$D$147,MATCH($G16,Schedule!$A$2:$A$147,0)),"") -> General Requirements & Temporary Works — Temporary bypass and interim effluent piping | V16: =IFERROR(INDEX(Schedule!$F$2:$F$147,MATCH("01-P01",Schedule!$A$2:$A$147,0)),"") -> 44999 | W16: Y | X16: N | Y16: 6 | Z16: 0 | AA16: PROPOSED-Temporary bypass pumping system (Civil & Site) | AB16: #68, #250, #251 | AC16: Inferred | AD16: 1 | AF16: 01 33 00; 01 50 00 | AG16: 01 33 00; 01 50 00 | AH16: Contract & General
A17: Item | B17: CWP 01 | C17: PROPOSED-Temporary-Bypass-Alarm-Monitoring | D17: Temporary bypass alarm and status monitoring (cellular notification; wired to the existing WWTP control system) | E17: Not stated | F17: Temporary | G17: 01-C01 | H17: =IFERROR(INDEX(Schedule!$E$2:$E$147,MATCH($G17,Schedule!$A$2:$A$147,0)),"") -> 45017 | I17: =IFERROR(INDEX(Schedule!$F$2:$F$147,MATCH($G17,Schedule!$A$2:$A$147,0)),"") -> 45210 | O17: 1 | P17: =IFERROR((IF(OR(ISNUMBER(J17),UPPER(TRIM(J17))="N/A"),1,0)*IF($W17="N",0,INDEX('Rules of Credit'!$B$5:$F$8,MATCH($F17,'Rules of Credit'!$A$5:$A$8,0),1))+IF(OR(ISNUMBER(K17),UPPER(TRIM(K17))="N/A"),1,0)*INDEX('Rules of Credit'!$B$5:$F$8,MATCH($F17,'Rules of Credit'!$A$5:$A$8,0),2)+IF(OR(ISNUMBER(L17),UPPER(TRIM(L17))="N/A"),1,0)*INDEX('Rules of Credit'!$B$5:$F$8,MATCH($F17,'Rules of Credit'!$A$5:$A$8,0),3)+IF(OR(ISNUMBER(M17),UPPER(TRIM(M17))="N/A"),1,0)*IF($X17="N",0,INDEX('Rules of Credit'!$B$5:$F$8,MATCH($F17,'Rules of Credit'!$A$5:$A$8,0),4))+IF(OR(ISNUMBER(N17),UPPER(TRIM(N17))="N/A"),1,0)*INDEX('Rules of Credit'!$B$5:$F$8,MATCH($F17,'Rules of Credit'!$A$5:$A$8,0),5))/(IF($W17="N",0,INDEX('Rules of Credit'!$B$5:$F$8,MATCH($F17,'Rules of Credit'!$A$5:$A$8,0),1))+INDEX('Rules of Credit'!$B$5:$F$8,MATCH($F17,'Rules of Credit'!$A$5:$A$8,0),2)+INDEX('Rules of Credit'!$B$5:$F$8,MATCH($F17,'Rules of Credit'!$A$5:$A$8,0),3)+IF($X17="N",0,INDEX('Rules of Credit'!$B$5:$F$8,MATCH($F17,'Rules of Credit'!$A$5:$A$8,0),4))+INDEX('Rules of Credit'!$B$5:$F$8,MATCH($F17,'Rules of Credit'!$A$5:$A$8,0),5)),0) -> 0 | Q17: =IF(OR($H17="",$I17=""),0,IF('Tracker Summary'!$C$3<$H17,0,IF('Tracker Summary'!$C$3>=$I17,1,('Tracker Summary'!$C$3-$H17)/($I17-$H17+1)))) -> 0 | R17: =P17-Q17 -> 0 | S17: =IF($I17="","Not scheduled",IF(P17>=1,"Complete",IF('Tracker Summary'!$C$3>$I17,"Overdue",IF(P17-Q17<-0.1,"Behind",IF(AND(P17=0,'Tracker Summary'!$C$3<$H17),"Not started","On track"))))) -> Not started | U17: =IFERROR(INDEX(Schedule!$D$2:$D$147,MATCH($G17,Schedule!$A$2:$A$147,0)),"") -> General Requirements & Temporary Works — Temporary bypass and interim effluent piping | V17: =IFERROR(INDEX(Schedule!$F$2:$F$147,MATCH("01-P01",Schedule!$A$2:$A$147,0)),"") -> 44999 | W17: N | X17: N | Y17: 0 | Z17: 0 | AA17: PROPOSED-Temporary bypass pumping system (Civil & Site) | AB17: #68, #253 | AC17: Inferred | AD17: 1 | AF17: 01 50 00 | AG17: 01 50 00 | AH17: Contract & General
A18: Section | B18: CWP 02 | C18: Demolition & Existing Conditions | D18: =COUNTIF(A19:A39,"Item")&" items · "&COUNTIF(S19:S39,"Overdue")&" overdue · "&COUNTIF(S19:S39,"Complete")&" complete" -> 21 items · 0 overdue · 0 complete | H18: =MIN(H19:H39) -> 45017 | I18: =MAX(I19:I39) -> 45443 | O18: =SUM(O19:O39) -> 21 | P18: =IFERROR(SUMPRODUCT(O19:O39,P19:P39)/SUM(O19:O39),0) -> 0 | Q18: =IFERROR(SUMPRODUCT(O19:O39,Q19:Q39)/SUM(O19:O39),0) -> 0 | R18: =P18-Q18 -> 0
A19: Item | B19: CWP 02 | C19: PROPOSED-Existing 8in effluent outfall pipe | D19: Existing 8-inch effluent (outfall) pipe, 40 LF — abandon and remove | E19: Site | F19: Remove | G19: 02-C02 | H19: =IFERROR(INDEX(Schedule!$E$2:$E$147,MATCH($G19,Schedule!$A$2:$A$147,0)),"") -> 45017 | I19: =IFERROR(INDEX(Schedule!$F$2:$F$147,MATCH($G19,Schedule!$A$2:$A$147,0)),"") -> 45077 | O19: 1 | P19: =IFERROR((IF(OR(ISNUMBER(J19),UPPER(TRIM(J19))="N/A"),1,0)*IF($W19="N",0,INDEX('Rules of Credit'!$B$5:$F$8,MATCH($F19,'Rules of Credit'!$A$5:$A$8,0),1))+IF(OR(ISNUMBER(K19),UPPER(TRIM(K19))="N/A"),1,0)*INDEX('Rules of Credit'!$B$5:$F$8,MATCH($F19,'Rules of Credit'!$A$5:$A$8,0),2)+IF(OR(ISNUMBER(L19),UPPER(TRIM(L19))="N/A"),1,0)*INDEX('Rules of Credit'!$B$5:$F$8,MATCH($F19,'Rules of Credit'!$A$5:$A$8,0),3)+IF(OR(ISNUMBER(M19),UPPER(TRIM(M19))="N/A"),1,0)*IF($X19="N",0,INDEX('Rules of Credit'!$B$5:$F$8,MATCH($F19,'Rules of Credit'!$A$5:$A$8,0),4))+IF(OR(ISNUMBER(N19),UPPER(TRIM(N19))="N/A"),1,0)*INDEX('Rules of Credit'!$B$5:$F$8,MATCH($F19,'Rules of Credit'!$A$5:$A$8,0),5))/(IF($W19="N",0,INDEX('Rules of Credit'!$B$5:$F$8,MATCH($F19,'Rules of Credit'!$A$5:$A$8,0),1))+INDEX('Rules of Credit'!$B$5:$F$8,MATCH($F19,'Rules of Credit'!$A$5:$A$8,0),2)+INDEX('Rules of Credit'!$B$5:$F$8,MATCH($F19,'Rules of Credit'!$A$5:$A$8,0),3)+IF($X19="N",0,INDEX('Rules of Credit'!$B$5:$F$8,MATCH($F19,'Rules of Credit'!$A$5:$A$8,0),4))+INDEX('Rules of Credit'!$B$5:$F$8,MATCH($F19,'Rules of Credit'!$A$5:$A$8,0),5)),0) -> 0 | Q19: =IF(OR($H19="",$I19=""),0,IF('Tracker Summary'!$C$3<$H19,0,IF('Tracker Summary'!$C$3>=$I19,1,('Tracker Summary'!$C$3-$H19)/($I19-$H19+1)))) -> 0 | R19: =P19-Q19 -> 0 | S19: =IF($I19="","Not scheduled",IF(P19>=1,"Complete",IF('Tracker Summary'!$C$3>$I19,"Overdue",IF(P19-Q19<-0.1,"Behind",IF(AND(P19=0,'Tracker Summary'!$C$3<$H19),"Not started","On track"))))) -> Not started | U19: =IFERROR(INDEX(Schedule!$D$2:$D$147,MATCH($G19,Schedule!$A$2:$A$147,0)),"") -> Demolition & Existing Conditions — Site demolition ahead of new work | V19: =IFERROR(INDEX(Schedule!$F$2:$F$147,MATCH("02-P01",Schedule!$A$2:$A$147,0)),"") -> 45016 | W19: N | X19: N | Y19: 0 | Z19: 0 | AC19: Inferred | AD19: 1 | AE19: C0.5 (KN 1); C0.7 (cited) | AF19: 02 41 00 | AG19: C0.5; 02 41 00 | AH19: Civil & Site
A20: Item | B20: CWP 02 | C20: PROPOSED-Existing 4in roof drain pipe | D20: Existing 4-inch roof drain pipe, 40 LF — abandon and remove | E20: Site | F20: Remove | G20: 02-C02 | H20: =IFERROR(INDEX(Schedule!$E$2:$E$147,MATCH($G20,Schedule!$A$2:$A$147,0)),"") -> 45017 | I20: =IFERROR(INDEX(Schedule!$F$2:$F$147,MATCH($G20,Schedule!$A$2:$A$147,0)),"") -> 45077 | O20: 1 | P20: =IFERROR((IF(OR(ISNUMBER(J20),UPPER(TRIM(J20))="N/A"),1,0)*IF($W20="N",0,INDEX('Rules of Credit'!$B$5:$F$8,MATCH($F20,'Rules of Credit'!$A$5:$A$8,0),1))+IF(OR(ISNUMBER(K20),UPPER(TRIM(K20))="N/A"),1,0)*INDEX('Rules of Credit'!$B$5:$F$8,MATCH($F20,'Rules of Credit'!$A$5:$A$8,0),2)+IF(OR(ISNUMBER(L20),UPPER(TRIM(L20))="N/A"),1,0)*INDEX('Rules of Credit'!$B$5:$F$8,MATCH($F20,'Rules of Credit'!$A$5:$A$8,0),3)+IF(OR(ISNUMBER(M20),UPPER(TRIM(M20))="N/A"),1,0)*IF($X20="N",0,INDEX('Rules of Credit'!$B$5:$F$8,MATCH($F20,'Rules of Credit'!$A$5:$A$8,0),4))+IF(OR(ISNUMBER(N20),UPPER(TRIM(N20))="N/A"),1,0)*INDEX('Rules of Credit'!$B$5:$F$8,MATCH($F20,'Rules of Credit'!$A$5:$A$8,0),5))/(IF($W20="N",0,INDEX('Rules of Credit'!$B$5:$F$8,MATCH($F20,'Rules of Credit'!$A$5:$A$8,0),1))+INDEX('Rules of Credit'!$B$5:$F$8,MATCH($F20,'Rules of Credit'!$A$5:$A$8,0),2)+INDEX('Rules of Credit'!$B$5:$F$8,MATCH($F20,'Rules of Credit'!$A$5:$A$8,0),3)+IF($X20="N",0,INDEX('Rules of Credit'!$B$5:$F$8,MATCH($F20,'Rules of Credit'!$A$5:$A$8,0),4))+INDEX('Rules of Credit'!$B$5:$F$8,MATCH($F20,'Rules of Credit'!$A$5:$A$8,0),5)),0) -> 0 | Q20: =IF(OR($H20="",$I20=""),0,IF('Tracker Summary'!$C$3<$H20,0,IF('Tracker Summary'!$C$3>=$I20,1,('Tracker Summary'!$C$3-$H20)/($I20-$H20+1)))) -> 0 | R20: =P20-Q20 -> 0 | S20: =IF($I20="","Not scheduled",IF(P20>=1,"Complete",IF('Tracker Summary'!$C$3>$I20,"Overdue",IF(P20-Q20<-0.1,"Behind",IF(AND(P20=0,'Tracker Summary'!$C$3<$H20),"Not started","On track"))))) -> Not started | U20: =IFERROR(INDEX(Schedule!$D$2:$D$147,MATCH($G20,Schedule!$A$2:$A$147,0)),"") -> Demolition & Existing Conditions — Site demolition ahead of new work | V20: =IFERROR(INDEX(Schedule!$F$2:$F$147,MATCH("02-P01",Schedule!$A$2:$A$147,0)),"") -> 45016 | W20: N | X20: N | Y20: 0 | Z20: 0 | AC20: Inferred | AD20: 1 | AE20: C0.5 (KN 2) | AF20: 02 41 00 | AG20: C0.5; 02 41 00 | AH20: Civil & Site
A21: Item | B21: CWP 02 | C21: SSMH 1286 | D21: Existing sump pump station (sewage pump) — remove | E21: Site | F21: Remove | G21: 02-C02 | H21: =IFERROR(INDEX(Schedule!$E$2:$E$147,MATCH($G21,Schedule!$A$2:$A$147,0)),"") -> 45017 | I21: =IFERROR(INDEX(Schedule!$F$2:$F$147,MATCH($G21,Schedule!$A$2:$A$147,0)),"") -> 45077 | O21: 1 | P21: =IFERROR((IF(OR(ISNUMBER(J21),UPPER(TRIM(J21))="N/A"),1,0)*IF($W21="N",0,INDEX('Rules of Credit'!$B$5:$F$8,MATCH($F21,'Rules of Credit'!$A$5:$A$8,0),1))+IF(OR(ISNUMBER(K21),UPPER(TRIM(K21))="N/A"),1,0)*INDEX('Rules of Credit'!$B$5:$F$8,MATCH($F21,'Rules of Credit'!$A$5:$A$8,0),2)+IF(OR(ISNUMBER(L21),UPPER(TRIM(L21))="N/A"),1,0)*INDEX('Rules of Credit'!$B$5:$F$8,MATCH($F21,'Rules of Credit'!$A$5:$A$8,0),3)+IF(OR(ISNUMBER(M21),UPPER(TRIM(M21))="N/A"),1,0)*IF($X21="N",0,INDEX('Rules of Credit'!$B$5:$F$8,MATCH($F21,'Rules of Credit'!$A$5:$A$8,0),4))+IF(OR(ISNUMBER(N21),UPPER(TRIM(N21))="N/A"),1,0)*INDEX('Rules of Credit'!$B$5:$F$8,MATCH($F21,'Rules of Credit'!$A$5:$A$8,0),5))/(IF($W21="N",0,INDEX('Rules of Credit'!$B$5:$F$8,MATCH($F21,'Rules of Credit'!$A$5:$A$8,0),1))+INDEX('Rules of Credit'!$B$5:$F$8,MATCH($F21,'Rules of Credit'!$A$5:$A$8,0),2)+INDEX('Rules of Credit'!$B$5:$F$8,MATCH($F21,'Rules of Credit'!$A$5:$A$8,0),3)+IF($X21="N",0,INDEX('Rules of Credit'!$B$5:$F$8,MATCH($F21,'Rules of Credit'!$A$5:$A$8,0),4))+INDEX('Rules of Credit'!$B$5:$F$8,MATCH($F21,'Rules of Credit'!$A$5:$A$8,0),5)),0) -> 0 | Q21: =IF(OR($H21="",$I21=""),0,IF('Tracker Summary'!$C$3<$H21,0,IF('Tracker Summary'!$C$3>=$I21,1,('Tracker Summary'!$C$3-$H21)/($I21-$H21+1)))) -> 0 | R21: =P21-Q21 -> 0 | S21: =IF($I21="","Not scheduled",IF(P21>=1,"Complete",IF('Tracker Summary'!$C$3>$I21,"Overdue",IF(P21-Q21<-0.1,"Behind",IF(AND(P21=0,'Tracker Summary'!$C$3<$H21),"Not started","On track"))))) -> Not started | U21: =IFERROR(INDEX(Schedule!$D$2:$D$147,MATCH($G21,Schedule!$A$2:$A$147,0)),"") -> Demolition & Existing Conditions — Site demolition ahead of new work | V21: =IFERROR(INDEX(Schedule!$F$2:$F$147,MATCH("02-P01",Schedule!$A$2:$A$147,0)),"") -> 45016 | W21: N | X21: N | Y21: 0 | Z21: 0 | AC21: Inferred | AD21: 1 | AE21: C0.5 (KN 3, 5); C0.1 | AF21: 02 41 00 | AG21: C0.5; C0.1; 02 41 00 | AH21: Civil & Site
A22: Item | B22: CWP 02 | C22: SSMH 1285 | D22: Existing septic tank — remove | E22: Site | F22: Remove | G22: 02-C02 | H22: =IFERROR(INDEX(Schedule!$E$2:$E$147,MATCH($G22,Schedule!$A$2:$A$147,0)),"") -> 45017 | I22: =IFERROR(INDEX(Schedule!$F$2:$F$147,MATCH($G22,Schedule!$A$2:$A$147,0)),"") -> 45077 | O22: 1 | P22: =IFERROR((IF(OR(ISNUMBER(J22),UPPER(TRIM(J22))="N/A"),1,0)*IF($W22="N",0,INDEX('Rules of Credit'!$B$5:$F$8,MATCH($F22,'Rules of Credit'!$A$5:$A$8,0),1))+IF(OR(ISNUMBER(K22),UPPER(TRIM(K22))="N/A"),1,0)*INDEX('Rules of Credit'!$B$5:$F$8,MATCH($F22,'Rules of Credit'!$A$5:$A$8,0),2)+IF(OR(ISNUMBER(L22),UPPER(TRIM(L22))="N/A"),1,0)*INDEX('Rules of Credit'!$B$5:$F$8,MATCH($F22,'Rules of Credit'!$A$5:$A$8,0),3)+IF(OR(ISNUMBER(M22),UPPER(TRIM(M22))="N/A"),1,0)*IF($X22="N",0,INDEX('Rules of Credit'!$B$5:$F$8,MATCH($F22,'Rules of Credit'!$A$5:$A$8,0),4))+IF(OR(ISNUMBER(N22),UPPER(TRIM(N22))="N/A"),1,0)*INDEX('Rules of Credit'!$B$5:$F$8,MATCH($F22,'Rules of Credit'!$A$5:$A$8,0),5))/(IF($W22="N",0,INDEX('Rules of Credit'!$B$5:$F$8,MATCH($F22,'Rules of Credit'!$A$5:$A$8,0),1))+INDEX('Rules of Credit'!$B$5:$F$8,MATCH($F22,'Rules of Credit'!$A$5:$A$8,0),2)+INDEX('Rules of Credit'!$B$5:$F$8,MATCH($F22,'Rules of Credit'!$A$5:$A$8,0),3)+IF($X22="N",0,INDEX('Rules of Credit'!$B$5:$F$8,MATCH($F22,'Rules of Credit'!$A$5:$A$8,0),4))+INDEX('Rules of Credit'!$B$5:$F$8,MATCH($F22,'Rules of Credit'!$A$5:$A$8,0),5)),0) -> 0 | Q22: =IF(OR($H22="",$I22=""),0,IF('Tracker Summary'!$C$3<$H22,0,IF('Tracker Summary'!$C$3>=$I22,1,('Tracker Summary'!$C$3-$H22)/($I22-$H22+1)))) -> 0 | R22: =P22-Q22 -> 0 | S22: =IF($I22="","Not scheduled",IF(P22>=1,"Complete",IF('Tracker Summary'!$C$3>$I22,"Overdue",IF(P22-Q22<-0.1,"Behind",IF(AND(P22=0,'Tracker Summary'!$C$3<$H22),"Not started","On track"))))) -> Not started | U22: =IFERROR(INDEX(Schedule!$D$2:$D$147,MATCH($G22,Schedule!$A$2:$A$147,0)),"") -> Demolition & Existing Conditions — Site demolition ahead of new work | V22: =IFERROR(INDEX(Schedule!$F$2:$F$147,MATCH("02-P01",Schedule!$A$2:$A$147,0)),"") -> 45016 | W22: N | X22: N | Y22: 0 | Z22: 0 | AC22: Inferred | AD22: 1 | AE22: C0.5 (KN 4); C0.1 | AF22: 02 41 00 | AG22: C0.5; C0.1; 02 41 00 | AH22: Civil & Site
A23: Item | B23: CWP 02 | C23: PROPOSED-Existing 10in effluent outfall pipe | D23: Existing 10-inch effluent (outfall) pipe, 60 LF — abandon and remove | E23: Site | F23: Remove | G23: 02-C02 | H23: =IFERROR(INDEX(Schedule!$E$2:$E$147,MATCH($G23,Schedule!$A$2:$A$147,0)),"") -> 45017 | I23: =IFERROR(INDEX(Schedule!$F$2:$F$147,MATCH($G23,Schedule!$A$2:$A$147,0)),"") -> 45077 | O23: 1 | P23: =IFERROR((IF(OR(ISNUMBER(J23),UPPER(TRIM(J23))="N/A"),1,0)*IF($W23="N",0,INDEX('Rules of Credit'!$B$5:$F$8,MATCH($F23,'Rules of Credit'!$A$5:$A$8,0),1))+IF(OR(ISNUMBER(K23),UPPER(TRIM(K23))="N/A"),1,0)*INDEX('Rules of Credit'!$B$5:$F$8,MATCH($F23,'Rules of Credit'!$A$5:$A$8,0),2)+IF(OR(ISNUMBER(L23),UPPER(TRIM(L23))="N/A"),1,0)*INDEX('Rules of Credit'!$B$5:$F$8,MATCH($F23,'Rules of Credit'!$A$5:$A$8,0),3)+IF(OR(ISNUMBER(M23),UPPER(TRIM(M23))="N/A"),1,0)*IF($X23="N",0,INDEX('Rules of Credit'!$B$5:$F$8,MATCH($F23,'Rules of Credit'!$A$5:$A$8,0),4))+IF(OR(ISNUMBER(N23),UPPER(TRIM(N23))="N/A"),1,0)*INDEX('Rules of Credit'!$B$5:$F$8,MATCH($F23,'Rules of Credit'!$A$5:$A$8,0),5))/(IF($W23="N",0,INDEX('Rules of Credit'!$B$5:$F$8,MATCH($F23,'Rules of Credit'!$A$5:$A$8,0),1))+INDEX('Rules of Credit'!$B$5:$F$8,MATCH($F23,'Rules of Credit'!$A$5:$A$8,0),2)+INDEX('Rules of Credit'!$B$5:$F$8,MATCH($F23,'Rules of Credit'!$A$5:$A$8,0),3)+IF($X23="N",0,INDEX('Rules of Credit'!$B$5:$F$8,MATCH($F23,'Rules of Credit'!$A$5:$A$8,0),4))+INDEX('Rules of Credit'!$B$5:$F$8,MATCH($F23,'Rules of Credit'!$A$5:$A$8,0),5)),0) -> 0 | Q23: =IF(OR($H23="",$I23=""),0,IF('Tracker Summary'!$C$3<$H23,0,IF('Tracker Summary'!$C$3>=$I23,1,('Tracker Summary'!$C$3-$H23)/($I23-$H23+1)))) -> 0 | R23: =P23-Q23 -> 0 | S23: =IF($I23="","Not scheduled",IF(P23>=1,"Complete",IF('Tracker Summary'!$C$3>$I23,"Overdue",IF(P23-Q23<-0.1,"Behind",IF(AND(P23=0,'Tracker Summary'!$C$3<$H23),"Not started","On track"))))) -> Not started | U23: =IFERROR(INDEX(Schedule!$D$2:$D$147,MATCH($G23,Schedule!$A$2:$A$147,0)),"") -> Demolition & Existing Conditions — Site demolition ahead of new work | V23: =IFERROR(INDEX(Schedule!$F$2:$F$147,MATCH("02-P01",Schedule!$A$2:$A$147,0)),"") -> 45016 | W23: N | X23: N | Y23: 0 | Z23: 0 | AC23: Inferred | AD23: 1 | AE23: C0.5 (KN 8) | AF23: 02 41 00 | AG23: C0.5; 02 41 00 | AH23: Civil & Site
