Workbook

Sheet QC Requirements
A1: Eastsound WWTP Upgrade Phase I — QC Requirements (one page)
A2: One row per QC log the field keeps, rolled up from the Inspection & Test Plan lines. Values are quoted from the cited paragraphs through the Project Wiki; line-by-line test values (by pipe or structure) stay in the ITP by design. Who pays follows 01 45 00 ¶1.05.B. The QA plan is informational, not a Contract Document.
A4: # | B4: QC log | C4: CWPs | D4: What to record | E4: When / how often | F4: Acceptance criteria (as stated) | G4: Performed / paid by | H4: Witness / notice | I4: Governing sections | J4: ITP lines, primary + also (formula) | K4: Tracker step | L4: Tag | M4: Gaps / notes
A5: 1 | B5: Inspection notice & hold-point log | C5: All | D5: Date and time notice sent; who was notified (Engineer, Owner, County, special inspector); work and location; inspection or test; result; re-inspection. | E5: Before every inspection, witnessed test, shutdown or tie-in. | F5: Notice: 48 h before work needing inspection (01 45 00); 48 h for witnessed pipe tests (33 30 00 ¶3.04); 24 h for dewatering discharge tests (31 23 19); 1 week to the Engineer for VFD start-up (26 29 23 ¶3.03); start-up procedures 14 days ahead (01 70 00 ¶1.06). Plant disruptions limited to 1 hour (Appendix F §5.1–5.2). Removals and tie-ins only after the replacement is tested (C0.5, C3.1). | G5: Contractor gives notice. Inspection beyond 40 hr/week is charged at $150/hr (00 73 00 SC 7–14). | H5: Engineer; Owner; County — footings, concrete structures, electrical, final (G0.3); special inspector (S1.1). | I5: 01 45 00 ¶1.05; 33 30 00 ¶3.04; 31 23 19 ¶3.2; 26 29 23 ¶3.03; 01 70 00 ¶1.06; 00 73 00 SC 7–14; G0.3; C0.5; C3.1; Appendix F §5 | J5: =COUNTIF('ITP Line Map'!$C$2:$C$200,A5)+SUMPRODUCT(--ISNUMBER(SEARCH(","&A5&",",","&SUBSTITUTE(SUBSTITUTE('ITP Line Map'!$D$2:$D$200,"#","")," ","")&","))) -> 7 | K5: All steps with a witness | L5: Verified | M5: Requirements_Schema.csv has no hold/witness column (Issues Log). Appendix F is not a Contract Document.
A6: 2 | B6: Test report & retest register | C6: All | D6: Test; laboratory; sample and location; date; result; pass or fail; report copies sent; failure, retest and who pays. | E6: Every test; reports as issued. | F6: Owner-approved laboratories only. Test reports in 3 copies, product certificates in triplicate (01 33 00 ¶1.04–1.05). The Contractor keeps records of all inspections and tests and pays for repeat tests after any failure, including Owner-responsibility tests (01 45 00 ¶1.05.A–E, ¶1.06.C). | G6: Split per 01 45 00 ¶1.05.B: Contractor pays pipe pressure, potable disinfection, equipment, clean-water leakage and mechanical tests; Owner pays special inspections, earthwork, concrete, asphalt, coatings and field welding. | H6: — | I6: 01 45 00 ¶1.05.A–E, ¶1.06.C; 01 33 00 ¶1.04–1.05 | J6: =COUNTIF('ITP Line Map'!$C$2:$C$200,A6)+SUMPRODUCT(--ISNUMBER(SEARCH(","&A6&",",","&SUBSTITUTE(SUBSTITUTE('ITP Line Map'!$D$2:$D$200,"#","")," ","")&","))) -> 7 | K6: Tested / inspected | L6: Verified | M6: No non-conformance procedure beyond retests is specified.
A7: 3 | B7: Material receiving inspection log | C7: All | D7: Item or tag; delivery date; condition; labels and original containers; certificates received; storage; shortages or damage. | E7: Each delivery. | F7: Products arrive in labeled original containers, are inspected on delivery, are accepted only when unloading forces are on site, and are stored per the manufacturer (01 60 00 ¶1.04–1.05). Product certificates in triplicate (01 33 00). | G7: Contractor. | H7: — | I7: 01 60 00 ¶1.04–1.05; 01 33 00 ¶1.05 | J7: =COUNTIF('ITP Line Map'!$C$2:$C$200,A7)+SUMPRODUCT(--ISNUMBER(SEARCH(","&A7&",",","&SUBSTITUTE(SUBSTITUTE('ITP Line Map'!$D$2:$D$200,"#","")," ","")&","))) -> 2 | K7: On site / ready | L7: Verified
A8: 4 | B8: Survey & layout verification log | C8: 03; site | D8: Control used; layout checked; anchor bolt positions against tolerance; monuments disturbed and replaced. | E8: Before placements; anchor bolts before concrete; monuments as disturbed. | F8: Anchor bolts to AISC 303-16 §7.5 tolerances, set by a registered land surveyor (03 30 00 ¶3.012 A). Disturbed survey monuments need a WA DNR permit (WAC 332-120) and replacement by a registered land surveyor at Contractor cost (G0.3). | G8: Contractor. | H8: — | I8: 03 30 00 ¶3.012 A; G0.3; 00 73 00 SC 7–14 | J8: =COUNTIF('ITP Line Map'!$C$2:$C$200,A8)+SUMPRODUCT(--ISNUMBER(SEARCH(","&A8&",",","&SUBSTITUTE(SUBSTITUTE('ITP Line Map'!$D$2:$D$200,"#","")," ","")&","))) -> 3 | K8: Installed / removed | L8: Unresolved | M8: Who stakes the work conflicts: 00 73 00 SC 7–14 says the Contractor; G0.3 Note 9 says the Engineer (Civil & Site CS-32).
A9: 5 | B9: Soils & compaction test log | C9: 31; 33; 03; 32 | D9: Location or station; lift; material; proctor (MDD, optimum moisture); field density %; pass or fail; retests; imported-material gradations. | E9: One test per 100 LF of roadway, 1,000 SF of subgrade, 500 CY of structural backfill (31 20 00 ¶1.03); retaining wall foundation soils before the leveling pad (32 32 23 ¶3.01). | F9: Structural fill 95% MDD (ASTM D1557) in 10-in loose lifts (31 20 00 ¶3.03). Pipe bedding 90% MDD in 6-in lifts; trench backfill 95% under paving or within 5 ft of roadway, 90% in landscaped areas (31 23 33 ¶3.03–3.04). | G9: Owner — the Engineer's independent lab (01 45 00 ¶1.05.B.2). Contractor pays retests and submits gradations and proctors for imported material (31 20 00 ¶1.02; 31 23 33 ¶1.05 C). | H9: Engineer's laboratory. | I9: 31 20 00 ¶1.02–1.03, ¶3.03; 31 23 33 ¶3.03–3.04; 32 32 23 ¶3.01; 01 45 00; QA plan §7 | J9: =COUNTIF('ITP Line Map'!$C$2:$C$200,A9)+SUMPRODUCT(--ISNUMBER(SEARCH(","&A9&",",","&SUBSTITUTE(SUBSTITUTE('ITP Line Map'!$D$2:$D$200,"#","")," ","")&","))) -> 6 | K9: Tested / inspected | L9: Verified | M9: Bedding and backfill values conflict with C7.4 (Civil & Site Issues).
A10: 6 | B10: Concrete placement & testing log | C10: 03 | D10: Placement and location; mix; tickets; slump, air, temperature; cylinder sets and breaks; reinforcing and subgrade sign-off; curing. | E10: Slump, air and temperature on each initial load; 4 cylinders per mix per day or per 150 CY, whichever is less (QA plan §7). | F10: Per 03 30 00 — strength and slump limits are not carried in the Wiki note. | G10: Owner provides independent testing and inspection: subgrade compaction and moisture, reinforcing placement, concrete placement and cylinders (03 30 00 ¶1.07 B). Contractor coordinates. | H10: Special inspector (S1.1). | I10: 03 30 00 ¶1.07 B; 01 45 00 ¶1.05.B.2; S1.1; QA plan §7 (informational) | J10: =COUNTIF('ITP Line Map'!$C$2:$C$200,A10)+SUMPRODUCT(--ISNUMBER(SEARCH(","&A10&",",","&SUBSTITUTE(SUBSTITUTE('ITP Line Map'!$D$2:$D$200,"#","")," ","")&","))) -> 2 | K10: Tested / inspected | L10: Unresolved | M10: Acceptance values not captured in the Wiki; the QA plan frequencies are not a Contract Document.
A11: 7 | B11: Precast structure receiving & inspection log | C11: 03 | D11: Structure; supplier certification; mix design and material certificates; sealed shop drawings approved; plant inspection if made; delivery condition; exterior joint sealant. | E11: Mix designs 15 days ahead; at delivery; joints at setting. | F11: WA-engineer-sealed shop drawings and calculations; material certificates; 5 years of NPCA certification; Owner and Engineer may inspect the plant (03 40 00 ¶1.06–1.07). Exterior sealant at precast wet well and vault joints per Add. 4 Clarification 2 (Add. 4 governs). | G11: Contractor; Owner / Engineer plant inspection optional. | H11: — | I11: 03 40 00 ¶1.01, ¶1.06–1.07; Add. 4 p.1 Clarification 2 | J11: =COUNTIF('ITP Line Map'!$C$2:$C$200,A11)+SUMPRODUCT(--ISNUMBER(SEARCH(","&A11&",",","&SUBSTITUTE(SUBSTITUTE('ITP Line Map'!$D$2:$D$200,"#","")," ","")&","))) -> 1 | K11: On site / ready | L11: Verified
A12: 8 | B12: Special inspection log (structural) | C12: 03; 05; 13 | D12: Item; inspection type per the S1.1 schedule; inspector; date; result; deficiencies closed. | E12: Per the S1.1 special inspection schedule. | F12: Structural steel to AISC 303-16 with A325 bolts and E70XX welds, exterior steel hot-dip galvanized; schedule covers steel, concrete, post-installed anchors, and soils and foundations (S1.1). The Add. 4 dowels into the existing foundation need no special inspection (S2.3, Add. 4 p.9). | G12: Owner — building special inspections for concrete and structural steel, air barrier testing (WA Energy Code 402), field welding (01 45 00 ¶1.05.B.2). Contractor coordinates. | H12: Special inspector. | I12: S1.1; S2.3 (Add. 4 p.9); 01 45 00 ¶1.05.B.2 | J12: =COUNTIF('ITP Line Map'!$C$2:$C$200,A12)+SUMPRODUCT(--ISNUMBER(SEARCH(","&A12&",",","&SUBSTITUTE(SUBSTITUTE('ITP Line Map'!$D$2:$D$200,"#","")," ","")&","))) -> 7 | K12: Tested / inspected | L12: Verified-Visual | M12: Continuous vs periodic frequencies and acceptance per inspection type are not in the Wiki note.
A13: 9 | B13: Pipe pressure & leakage test log | C13: 33; 22; 43; 46 | D13: Line or segment; medium; test pressure; duration; gauge and calibration; pressure loss or leakage; witness; result. HDPE fusion data logs and destructive tests. Tracer wire locate test. | E13: After installation, before backfill or tie-in as the section requires; witnessed with 48-hour notice. | F13: Force mains at 1.5 × operating or 150 psi for 15 min; mixed liquor and West Plant Drain Pump Station force mains 150 psi; 2W and 3W piping 200 psi; HDPE per ASTM F2164 and PPI TN-802; valves tested with their pipelines (33 30 00 ¶3.04; 33 33 00 ¶3.04; 45 05 00 ¶3.02). Hydrants: 200 psi hydrostatic plus a flow test (33 32 00). Aeration air header: 15 psi, 60-minute low-pressure air test (46 53 00 ¶2.01 D–E). HDPE joints all visually inspected and data-logged; 3 joints or 3%, whichever is greater, destructively tested (33 33 00 ¶3.03). Tracer wire conductivity / locate test on completion (C7.1 Det. 6). | G13: Contractor (01 45 00 ¶1.05.B.1); Inspector present for all pipe testing (QA plan §7). | H13: Inspector / Engineer; 48-hour notice. | I13: 33 30 00 ¶3.04; 33 32 00; 33 33 00 ¶3.03–3.04; 45 05 00 ¶3.02; 46 53 00 ¶2.01 D–E; C7.1 | J13: =COUNTIF('ITP Line Map'!$C$2:$C$200,A13)+SUMPRODUCT(--ISNUMBER(SEARCH(","&A13&",",","&SUBSTITUTE(SUBSTITUTE('ITP Line Map'!$D$2:$D$200,"#","")," ","")&","))) -> 12 | K13: Tested / inspected | L13: Unresolved | M13: Gravity storm/sewer and water-line methods defer to WSDOT 4-04.3(1), 7-17.3(2), 7-09.3(23) — external reference, not staged. Values by line stay in the ITP.
A14: 10 | B14: Water line disinfection & bacteriological log | C14: 33 | D14: Line; chlorination date; initial chlorine; 24-hour residual; flushing; sample IDs; DOH-lab results. | E14: After the pressure test, before service. | F14: Chlorine 50 mg/L initial and 25 mg/L at 24 hours; bacteriological reports from a DOH lab (33 30 00 ¶3.04.7, 9). Water main work per 33 32 00 ¶3.05–3.06; only Association staff operate existing isolation valves. | G14: Contractor (01 45 00 ¶1.05.B.1). | H14: DOH-certified laboratory. | I14: 33 30 00 ¶3.04; 33 32 00 ¶3.05–3.06 | J14: =COUNTIF('ITP Line Map'!$C$2:$C$200,A14)+SUMPRODUCT(--ISNUMBER(SEARCH(","&A14&",",","&SUBSTITUTE(SUBSTITUTE('ITP Line Map'!$D$2:$D$200,"#","")," ","")&","))) -> 4 | K14: Tested / inspected | L14: Unresolved | M14: WSDOT 7-09.3(23) method not staged.
A15: 11 | B15: Structure clean-water leakage test log | C15: 03; 46; 43; 22 | D15: Structure; fill date and time; level at the rim; 2-hour readings; visible leakage; repairs; retest. | E15: Before start-up of each structure. | F15: Filled to the rim, held 2 hours, no visible leakage (01 45 00 ¶1.09). Structures: influent pump station, flow splitter, UV channels 1 and 2, aerobic digester, Train 3 aeration and anoxic basins and clarifier, 2W pump station wet well (01 45 00; 01 50 00 ¶1.04.C). | G15: Contractor (01 45 00 ¶1.05.B.1). | H15: Not stated. | I15: 01 45 00 ¶1.09; 01 50 00 ¶1.04.C; Appendix F §6.0 | J15: =COUNTIF('ITP Line Map'!$C$2:$C$200,A15)+SUMPRODUCT(--ISNUMBER(SEARCH(","&A15&",",","&SUBSTITUTE(SUBSTITUTE('ITP Line Map'!$D$2:$D$200,"#","")," ","")&","))) -> 4 | K15: Tested / inspected | L15: Verified | M15: The two structure lists name the structures differently (Contract & General Issues 1.22).
A16: 12 | B16: Equipment testing, start-up & training log | C16: 22; 23; 40; 41; 43; 46; 10 | D16: Tag; factory test certificate; manufacturer installation certification; motor amps and rotation; controls check; functional / performance test; clean-water mechanical tests; start-up sign-off; training hours and attendees; O&M manual reviewed. | E16: Factory tests before shipment; procedures 14 days before start-up; start-up witnessed; training before Substantial Completion. | F16: Blowers slip tested and run 30 min at maximum speed and differential; each package runs 15 min before shipment with a conformance certificate (43 11 00 ¶2.01 L–N). Influent pumps: certified factory performance tests to Hydraulic Institute standards and a factory operational test of the station (22 13 29 ¶1.04). Train 3: witnessed Functional Acceptance Test (46 53 00 ¶3.03). UV: 2 days start-up and field testing, 1 day training (46 66 00 ¶3.02). Supplier start-up and training minimums per 01 91 00 ¶1.01.B. All equipment tested before any facility operates, Engineer witness, joint sign-off (01 70 00 ¶1.06). | G16: Contractor pays equipment and clean-water mechanical testing (01 45 00 ¶1.05.B.1); manufacturers' representatives perform. | H16: Engineer (01 70 00 ¶1.06; QA plan §7). | I16: 01 70 00 ¶1.06; 01 91 00; 43 11 00; 22 13 29; 22 13 36; 46 41 23; 46 53 00; 46 66 00; 46 66 10; 46 76 26; 10 73 05 | J16: =COUNTIF('ITP Line Map'!$C$2:$C$200,A16)+SUMPRODUCT(--ISNUMBER(SEARCH(","&A16&",",","&SUBSTITUTE(SUBSTITUTE('ITP Line Map'!$D$2:$D$200,"#","")," ","")&","))) -> 19 | K16: Tested / inspected | L16: Verified | M16: 46 76 26 has no field start-up paragraph (Process & Mechanical Issue 37); 01 91 00 gives the press 1 or 2 days (Contract & General Issues 1.21).
A17: 13 | B17: Electrical testing & energization log (incl. generators) | C17: 26 | D17: Equipment or circuit; test; instrument; reading; pass or fail; date; witness. Generator load bank steps and transfer tests. | E17: Before energization; MCC shop test before shipment; VFD start-up with 1-week notice; generators at commissioning. | F17: Insulation resistance at 1,000 VDC for 30 s, 1 megohm minimum at 20 °C; continuity; thermal imaging of all power terminations; ground resistance 25 ohms per rod (three-rod method), 15 ohms composite (26 05 19 ¶3.07). Panelboard phase balance within 20% and torque checks (26 24 16). MCC shop-tested with the control system at rated voltage, every I/O point (26 24 19 ¶3.02). VFDs tested under motor load with simulated overload and 100% parameter verification, on utility and standby power (26 29 23). ATS factory dielectric test (NEMA ICS 1) and manufacturer field tests (26 36 00). Generator: resistive load bank at full load for at least 2 hours (NFPA 110), full fuel tank at final commissioning, 4 hours of training (26 32 13 ¶3.06–3.09). Temporary generator: connection and automatic load transfer test, 60 dBA or lower at full load (Add. 4 Clarification 5 — Add. 4 governs). | G17: Contractor; manufacturers' representatives for ATS and VFDs. | H17: Engineer (1-week notice for VFD start-up). | I17: 26 05 00 ¶3.04; 26 05 19 ¶3.07; 26 24 16; 26 24 19 ¶3.02; 26 29 23; 26 32 13 ¶3.06–3.09; 26 36 00; 26 51 19; Add. 4 Clarification 5 | J17: =COUNTIF('ITP Line Map'!$C$2:$C$200,A17)+SUMPRODUCT(--ISNUMBER(SEARCH(","&A17&",",","&SUBSTITUTE(SUBSTITUTE('ITP Line Map'!$D$2:$D$200,"#","")," ","")&","))) -> 12 | K17: Tested / inspected | L17: Verified
A18: 14 | B18: Controls & SCADA test log (factory and site acceptance) | C18: 26 | D18: I/O and loop checks; factory simulation; field acceptance test; alarm and float tests; programming changes; operator training. | E18: Factory simulation before shipment; field acceptance test before start-up. | F18: Factory simulation witnessed by the Engineer and Owner before shipment; field acceptance test and operator training by the system integrator, then programming, start-up and commissioning (26 80 00). Float test buttons and hardwired high-level backup circuits checked (E8.1, E8.3). | G18: Contractor through the system integrator; equipment suppliers commission packaged controls (26 80 00). | H18: Engineer and Owner (factory simulation). | I18: 26 80 00; E8.1; E8.3; E9.2 | J18: =COUNTIF('ITP Line Map'!$C$2:$C$200,A18)+SUMPRODUCT(--ISNUMBER(SEARCH(","&A18&",",","&SUBSTITUTE(SUBSTITUTE('ITP Line Map'!$D$2:$D$200,"#","")," ","")&","))) -> 6 | K18: Tested / inspected | L18: Verified-Visual
A19: 15 | B19: Coatings inspection log | C19: 09 | D19: Surface preparation; ambient conditions; wet and dry film thickness; holiday test; adhesion pulls; repairs. | E19: Each coat and test area. | F19: Wet-film readings (ASTM D4414); optional ultrasonic dry-film checks (SSPC-PA 9); holiday testing at 100 V/mil (NACE RP0188 or ASTM D4787); pull-off adhesion (ASTM D7234) with 2 of 3 pulls over 200 psi per test area; all documented to the Owner (09 97 23 ¶3.06). | G19: Owner-paid coatings inspection (01 45 00 ¶1.05.B.2). | H19: — | I19: 09 97 23 ¶3.06; 01 45 00 | J19: =COUNTIF('ITP Line Map'!$C$2:$C$200,A19)+SUMPRODUCT(--ISNUMBER(SEARCH(","&A19&",",","&SUBSTITUTE(SUBSTITUTE('ITP Line Map'!$D$2:$D$200,"#","")," ","")&","))) -> 4 | K19: Tested / inspected | L19: Verified
A20: 16 | B20: Asphalt paving QC log | C20: 32 | D20: Mix; asphalt content; gradation; voids; fracture; sand equivalent; in-place density; Rice density. | E20: During paving (frequency not stated). | F20: Contractor QC testing (asphalt content, gradation, voids, fracture, equivalence, in-place density) "with Section 01400", which is not in the manual (32 12 16 ¶3.05). Owner-paid asphalt testing: Rice density, compaction, extraction and gradation (01 45 00 ¶1.05.B.2). | G20: Contractor QC plus Owner QA. | H20: — | I20: 32 12 16 ¶3.05; 01 45 00 | J20: =COUNTIF('ITP Line Map'!$C$2:$C$200,A20)+SUMPRODUCT(--ISNUMBER(SEARCH(","&A20&",",","&SUBSTITUTE(SUBSTITUTE('ITP Line Map'!$D$2:$D$200,"#","")," ","")&","))) -> 2 | K20: Tested / inspected | L20: Unresolved | M20: "Section 01400" is cited but not in the project manual.
A21: 17 | B21: Dewatering & erosion control monitoring log | C21: 31 | D21: Dewatering discharge sand content; settlement point readings; BMP inspections, deficiencies, corrective actions, street sweeping. | E21: Discharge tests with 24-hour notice; settlement points near critical structures; BMPs periodically and after any impairment. | F21: Discharge no more than 10 ppm silica by Rossum sand tester (31 23 19 ¶3.2–3.3). BMP impairments corrected immediately; streets swept if soil migrates (31 32 11 ¶3.03). | G21: Contractor; the Owner joins BMP inspections. | H21: 24-hour notice for discharge tests. | I21: 31 23 19 ¶3.2–3.3; 31 32 11 ¶3.03 | J21: =COUNTIF('ITP Line Map'!$C$2:$C$200,A21)+SUMPRODUCT(--ISNUMBER(SEARCH(","&A21&",",","&SUBSTITUTE(SUBSTITUTE('ITP Line Map'!$D$2:$D$200,"#","")," ","")&","))) -> 2 | K21: Tested / inspected | L21: Unresolved | M21: Permit inspection frequency (NPDES / SWPPP) is outside the library.
A22: 18 | B22: Turnover & closeout checklist | C22: All | D22: Start-up testing and training complete; O&M manuals; spare parts, tools, extra stock; keys and lock changeover; record information; temporary facilities removed; cleanup; extinguisher tags; Substantial Completion systems in beneficial use. | E22: Before requesting Substantial Completion; again at Final Completion. | F22: Items in 01 70 00 ¶1.03.A. SC 19 defines Substantial Completion (influent pump station, flow splitter, Train 3, digester, dewatering, Blower Building, UV, yard piping, electrical, instruments, controls, backup generator, SCADA/PLC programming in beneficial use) and Final Completion (including removal of temporary pump and process equipment). Fire extinguishers visually inspected and tagged (10 52 00 ¶3.01 C). | G22: Contractor. | H22: Engineer and Owner. | I22: 01 70 00 ¶1.03.A; 00 73 00 SC 19; 10 52 00 ¶3.01 C | J22: =COUNTIF('ITP Line Map'!$C$2:$C$200,A22)+SUMPRODUCT(--ISNUMBER(SEARCH(","&A22&",",","&SUBSTITUTE(SUBSTITUTE('ITP Line Map'!$D$2:$D$200,"#","")," ","")&","))) -> 3 | K22: Turned over / closed | L22: Verified | M22: Temporary-facility removal timing conflicts (Contract & General Issues 1.19).
B24: ITP lines reconciled (formulas)
B25: Descriptive — no QC requirement | C25: =COUNTIF('ITP Line Map'!E:E,"Descriptive*") -> 23
B26: Gap lines (requirement not summarized; placed by division) | C26: =COUNTIF('ITP Line Map'!E:E,"Gap line*") -> 11
B27: Requirement lines rolled into a QC log | C27: =COUNTIF('ITP Line Map'!C:C,">0")-C26 -> 69
B28: Total ITP lines | C28: =COUNTA('ITP Line Map'!A:A)-1 -> 103

Sheet ITP Line Map
A1: ITP line | B1: ITP subtype | C1: QC log # | D1: Also used in | E1: Note | F1: QC log name (formula)
A2: ITP G0.3-01 | B2: Special inspection | C2: 1 | D2: #4, #8 | F2: =IF(C2="","",INDEX('QC Requirements'!$B$5:$B$22,C2)) -> Inspection notice & hold-point log
A3: ITP G0.6-01 | B3: Disinfection / bacteriological | E3: Descriptive line — no test or inspection requirement (keyword false positive in the ITP build) | F3: =IF(C3="","",INDEX('QC Requirements'!$B$5:$B$22,C3))
A4: ITP G0.7-01 | B4: Start-up / commissioning | E4: Descriptive line — no test or inspection requirement (keyword false positive in the ITP build) | F4: =IF(C4="","",INDEX('QC Requirements'!$B$5:$B$22,C4))
A5: ITP C0.5-01 | B5: Test / inspection | C5: 1 | E5: Sequence: removal after replacement is tested | F5: =IF(C5="","",INDEX('QC Requirements'!$B$5:$B$22,C5)) -> Inspection notice & hold-point log
A6: ITP C0.5-02 | B6: Test / inspection | C6: 1 | E6: Sequence: keep services live until replacements are tested | F6: =IF(C6="","",INDEX('QC Requirements'!$B$5:$B$22,C6)) -> Inspection notice & hold-point log
A7: ITP C1.3-01 | B7: Disinfection / bacteriological | E7: Descriptive line — no test or inspection requirement (keyword false positive in the ITP build) | F7: =IF(C7="","",INDEX('QC Requirements'!$B$5:$B$22,C7))
A8: ITP C1.4-01 | B8: Disinfection / bacteriological | E8: Descriptive line — no test or inspection requirement (keyword false positive in the ITP build) | F8: =IF(C8="","",INDEX('QC Requirements'!$B$5:$B$22,C8))
A9: ITP C2.4-01 | B9: Test / inspection | E9: Descriptive line — no test or inspection requirement (keyword false positive in the ITP build) | F9: =IF(C9="","",INDEX('QC Requirements'!$B$5:$B$22,C9))
A10: ITP C3.1-01 | B10: Test / inspection | C10: 1 | E10: Sequence: connect after the new splitter and piping are tested | F10: =IF(C10="","",INDEX('QC Requirements'!$B$5:$B$22,C10)) -> Inspection notice & hold-point log
A11: ITP C4.3-01 | B11: Field pressure / leakage test | E11: Descriptive line — no test or inspection requirement (keyword false positive in the ITP build) | F11: =IF(C11="","",INDEX('QC Requirements'!$B$5:$B$22,C11))
A12: ITP C5.1-01 | B12: Disinfection / bacteriological | E12: Descriptive line — no test or inspection requirement (keyword false positive in the ITP build) | F12: =IF(C12="","",INDEX('QC Requirements'!$B$5:$B$22,C12))
A13: ITP C5.4-01 | B13: Disinfection / bacteriological | E13: Descriptive line — no test or inspection requirement (keyword false positive in the ITP build) | F13: =IF(C13="","",INDEX('QC Requirements'!$B$5:$B$22,C13))
A14: ITP C7.1-01 | B14: Test / inspection | C14: 9 | F14: =IF(C14="","",INDEX('QC Requirements'!$B$5:$B$22,C14)) -> Pipe pressure & leakage test log
A15: ITP C7.3-01 | B15: Disinfection / bacteriological | E15: Descriptive line — no test or inspection requirement (keyword false positive in the ITP build) | F15: =IF(C15="","",INDEX('QC Requirements'!$B$5:$B$22,C15))
A16: ITP S1.1-01 | B16: Special inspection | C16: 8 | F16: =IF(C16="","",INDEX('QC Requirements'!$B$5:$B$22,C16)) -> Special inspection log (structural)
A17: ITP S2.3-01 | B17: Special inspection | C17: 8 | F17: =IF(C17="","",INDEX('QC Requirements'!$B$5:$B$22,C17)) -> Special inspection log (structural)
A18: ITP E0.3-01 | B18: Disinfection / bacteriological | E18: Descriptive line — no test or inspection requirement (keyword false positive in the ITP build) | F18: =IF(C18="","",INDEX('QC Requirements'!$B$5:$B$22,C18))
A19: ITP E0.4-01 | B19: Disinfection / bacteriological | E19: Descriptive line — no test or inspection requirement (keyword false positive in the ITP build) | F19: =IF(C19="","",INDEX('QC Requirements'!$B$5:$B$22,C19))
A20: ITP E4.1-01 | B20: Factory / shop test | C20: 12 | F20: =IF(C20="","",INDEX('QC Requirements'!$B$5:$B$22,C20)) -> Equipment testing, start-up & training log
A21: ITP E5.1-01 | B21: Disinfection / bacteriological | E21: Descriptive line — no test or inspection requirement (keyword false positive in the ITP build) | F21: =IF(C21="","",INDEX('QC Requirements'!$B$5:$B$22,C21))
A22: ITP E8.1-01 | B22: Test / inspection | C22: 14 | F22: =IF(C22="","",INDEX('QC Requirements'!$B$5:$B$22,C22)) -> Controls & SCADA test log (factory and site acceptance)
A23: ITP E8.3-01 | B23: Test / inspection | C23: 14 | F23: =IF(C23="","",INDEX('QC Requirements'!$B$5:$B$22,C23)) -> Controls & SCADA test log (factory and site acceptance)
A24: ITP E9.2-01 | B24: Test / inspection | C24: 14 | F24: =IF(C24="","",INDEX('QC Requirements'!$B$5:$B$22,C24)) -> Controls & SCADA test log (factory and site acceptance)
A25: ITP C1.6A-01 | B25: Disinfection / bacteriological | E25: Descriptive line — no test or inspection requirement (keyword false positive in the ITP build) | F25: =IF(C25="","",INDEX('QC Requirements'!$B$5:$B$22,C25))
A26: ITP 00 73 00-01 | B26: Test / inspection | C26: 1 | D26: #4 | F26: =IF(C26="","",INDEX('QC Requirements'!$B$5:$B$22,C26)) -> Inspection notice & hold-point log
A27: ITP 00 73 00-02 | B27: Test / inspection | C27: 18 | F27: =IF(C27="","",INDEX('QC Requirements'!$B$5:$B$22,C27)) -> Turnover & closeout checklist
A28: ITP 01 33 00-01 | B28: Test / inspection | C28: 2 | D28: #3 | F28: =IF(C28="","",INDEX('QC Requirements'!$B$5:$B$22,C28)) -> Test report & retest register
A29: ITP 01 45 00-01 | B29: Test / inspection | C29: 2 | D29: #1 | F29: =IF(C29="","",INDEX('QC Requirements'!$B$5:$B$22,C29)) -> Test report & retest register
A30: ITP 01 45 00-02 | B30: Field pressure / leakage test; Disinfection / bacteriological | C30: 2 | D30: #9, #10, #11, #12 | E30: Contractor-paid split | F30: =IF(C30="","",INDEX('QC Requirements'!$B$5:$B$22,C30)) -> Test report & retest register
A31: ITP 01 45 00-03 | B31: Field pressure / leakage test; Start-up / commissioning; Special inspection; Material testing; Disinfection / bacteriological | C31: 11 | D31: #2, #5, #6, #8, #15, #16 | E31: Owner-paid split; leakage test | F31: =IF(C31="","",INDEX('QC Requirements'!$B$5:$B$22,C31)) -> Structure clean-water leakage test log
A32: ITP 01 50 00-01 | B32: Field pressure / leakage test | C32: 11 | F32: =IF(C32="","",INDEX('QC Requirements'!$B$5:$B$22,C32)) -> Structure clean-water leakage test log
A33: ITP 01 60 00-01 | B33: Test / inspection | C33: 3 | F33: =IF(C33="","",INDEX('QC Requirements'!$B$5:$B$22,C33)) -> Material receiving inspection log
A34: ITP 01 70 00-01 | B34: Start-up / commissioning | C34: 18 | F34: =IF(C34="","",INDEX('QC Requirements'!$B$5:$B$22,C34)) -> Turnover & closeout checklist
A35: ITP 01 70 00-02 | B35: Start-up / commissioning | C35: 12 | D35: #13 | F35: =IF(C35="","",INDEX('QC Requirements'!$B$5:$B$22,C35)) -> Equipment testing, start-up & training log
A36: ITP 01 91 00-01 | B36: Start-up / commissioning; Training | C36: 12 | F36: =IF(C36="","",INDEX('QC Requirements'!$B$5:$B$22,C36)) -> Equipment testing, start-up & training log
A37: ITP 03 30 00-01 | B37: Special inspection; Material testing | C37: 6 | D37: #4, #8 | F37: =IF(C37="","",INDEX('QC Requirements'!$B$5:$B$22,C37)) -> Concrete placement & testing log
A38: ITP 03 40 00-01 | B38: Test / inspection | C38: 7 | F38: =IF(C38="","",INDEX('QC Requirements'!$B$5:$B$22,C38)) -> Precast structure receiving & inspection log
A39: ITP 09 97 23-01 | B39: Test / inspection | C39: 15 | F39: =IF(C39="","",INDEX('QC Requirements'!$B$5:$B$22,C39)) -> Coatings inspection log
A40: ITP 10 52 00-01 | B40: Test / inspection | C40: 18 | F40: =IF(C40="","",INDEX('QC Requirements'!$B$5:$B$22,C40)) -> Turnover & closeout checklist
...
